Workbook

Sheet mar_24
A1: Location | B1: NBIP-NBIP Calls Revenue | C1: Fixed Calls Revenue | D1: Telekom Calls Revenue | E1: BMobile Calls Revenue | F1: Intl Calls Revenue | G1: A2P SMS Revenue | H1: Telekom SMS Revenue | I1: BMobile SMS Revenue | J1: Intl SMS Revenue | K1: Mobile Data Revenue | L1: Total
A2: NBIP_ANUHA | B2: 0 | C2: 0 | D2: 0 | E2: 0 | F2: 0 | G2: 0 | H2: 0 | I2: 0 | J2: 0 | K2: 0 | L2: =SUM(B2:K2) -> 0
A3: NBIP_Babasu | B3: 0 | C3: 0 | D3: 0 | E3: 0 | F3: 0 | G3: 0 | H3: 0 | I3: 0 | J3: 0 | K3: 0 | L3: =SUM(B3:K3) -> 0
A4: NBIP_Bambakani | B4: 0 | C4: 0 | D4: 0 | E4: 0 | F4: 0 | G4: 0 | H4: 0 | I4: 0 | J4: 0 | K4: 0 | L4: =SUM(B4:K4) -> 0
A5: NBIP_Baniata | B5: 0 | C5: 0 | D5: 0 | E5: 0 | F5: 0 | G5: 0 | H5: 0 | I5: 0 | J5: 0 | K5: 0 | L5: =SUM(B5:K5) -> 0
A6: NBIP_BELAGA | B6: 0 | C6: 0 | D6: 0 | E6: 0 | F6: 0 | G6: 0 | H6: 0 | I6: 0 | J6: 0 | K6: 0 | L6: =SUM(B6:K6) -> 0
A7: NBIP_BITILA/KUSINI | B7: 0 | C7: 0 | D7: 0 | E7: 0 | F7: 0 | G7: 0 | H7: 0 | I7: 0 | J7: 0 | K7: 0 | L7: =SUM(B7:K7) -> 0
A8: NBIP_BOLITEI | B8: 0 | C8: 0 | D8: 0 | E8: 0 | F8: 0 | G8: 0 | H8: 0 | I8: 0 | J8: 0 | K8: 0 | L8: =SUM(B8:K8) -> 0
A9: NBIP_Bubunughu | B9: 0 | C9: 0 | D9: 0 | E9: 0 | F9: 0 | G9: 0 | H9: 0 | I9: 0 | J9: 0 | K9: 0 | L9: =SUM(B9:K9) -> 0
A10: NBIP_CHIVOKA | B10: 0 | C10: 0 | D10: 0 | E10: 0 | F10: 0 | G10: 0 | H10: 0 | I10: 0 | J10: 0 | K10: 0 | L10: =SUM(B10:K10) -> 0
A11: NBIP_Dokudula | B11: 0 | C11: 0 | D11: 0 | E11: 0 | F11: 0 | G11: 0 | H11: 0 | I11: 0 | J11: 0 | K11: 0 | L11: =SUM(B11:K11) -> 0
A12: NBIP_Gesa | B12: 0 | C12: 0 | D12: 0 | E12: 0 | F12: 0 | G12: 0 | H12: 0 | I12: 0 | J12: 0 | K12: 0 | L12: =SUM(B12:K12) -> 0
A13: NBIP_Ghombua | B13: 0 | C13: 0 | D13: 0 | E13: 0 | F13: 0 | G13: 0 | H13: 0 | I13: 0 | J13: 0 | K13: 0 | L13: =SUM(B13:K13) -> 0
... A60: Total | B60: 219.02 | C60: 5.89 | D60: 3692.42 | E60: 81.61 | F60: 6.8 | G60: 0.3 | H60: 140.6 | I60: 1.1 | J60: 0.5 | K60: 3349.73 | L60: =SUM(B60:K60) -> 7497.97

Sheet apr_24
A1: Location | B1: NBIP-NBIP Calls Revenue | C1: Fixed Calls Revenue | D1: Telekom Calls Revenue | E1: BMobile Calls Revenue | F1: Intl Calls Revenue | G1: A2P SMS Revenue | H1: Telekom SMS Revenue | I1: BMobile SMS Revenue | J1: Intl SMS Revenue | K1: Mobile Data Revenue | L1: Total
A2: NBIP_ANUHA | B2: 0 | C2: 0 | D2: 0 | E2: 0 | F2: 0 | G2: 0 | H2: 0 | I2: 0 | J2: 0 | K2: 0 | L2: =SUM(B2:K2) -> 0
A3: NBIP_Babasu | B3: 0 | C3: 0 | D3: 0 | E3: 0 | F3: 0 | G3: 0 | H3: 0 | I3: 0 | J3: 0 | K3: 0 | L3: =SUM(B3:K3) -> 0
A4: NBIP_Bambakani | B4: 0 | C4: 0 | D4: 0 | E4: 0 | F4: 0 | G4: 0 | H4: 0 | I4: 0 | J4: 0 | K4: 0 | L4: =SUM(B4:K4) -> 0
A5: NBIP_Baniata | B5: 0 | C5: 0 | D5: 0 | E5: 0 | F5: 0 | G5: 0 | H5: 0 | I5: 0 | J5: 0 | K5: 0 | L5: =SUM(B5:K5) -> 0
A6: NBIP_BELAGA | B6: 0 | C6: 0 | D6: 0 | E6: 0 | F6: 0 | G6: 0 | H6: 0 | I6: 0 | J6: 0 | K6: 0 | L6: =SUM(B6:K6) -> 0
A7: NBIP_BITILA/KUSINI | B7: 0 | C7: 0 | D7: 0 | E7: 0 | F7: 0 | G7: 0 | H7: 0 | I7: 0 | J7: 0 | K7: 0 | L7: =SUM(B7:K7) -> 0
A8: NBIP_BOLITEI | B8: 0 | C8: 0 | D8: 0 | E8: 0 | F8: 0 | G8: 0 | H8: 0 | I8: 0 | J8: 0 | K8: 0 | L8: =SUM(B8:K8) -> 0
A9: NBIP_Bubunughu | B9: 0 | C9: 0 | D9: 0 | E9: 0 | F9: 0 | G9: 0 | H9: 0 | I9: 0 | J9: 0 | K9: 0 | L9: =SUM(B9:K9) -> 0
A10: NBIP_CHIVOKA | B10: 0 | C10: 0 | D10: 0 | E10: 0 | F10: 0 | G10: 0 | H10: 0 | I10: 0 | J10: 0 | K10: 0 | L10: =SUM(B10:K10) -> 0
A11: NBIP_Dokudula | B11: 0 | C11: 0 | D11: 0 | E11: 0 | F11: 0 | G11: 0 | H11: 0 | I11: 0 | J11: 0 | K11: 0 | L11: =SUM(B11:K11) -> 0
A12: NBIP_Gesa | B12: 0 | C12: 0 | D12: 0 | E12: 0 | F12: 0 | G12: 0 | H12: 0 | I12: 0 | J12: 0 | K12: 0 | L12: =SUM(B12:K12) -> 0
A13: NBIP_Ghombua | B13: 0 | C13: 0 | D13: 0 | E13: 0 | F13: 0 | G13: 0 | H13: 0 | I13: 0 | J13: 0 | K13: 0 | L13: =SUM(B13:K13) -> 0
... A60: Total | B60: 1415.9 | C60: 39.47 | D60: 14130.05 | E60: 282.14 | F60: 49.69 | G60: 11.6 | H60: 466.2 | I60: 5.9 | J60: 14.8 | K60: 24139.58 | L60: =SUM(B60:K60) -> 40555.33

Sheet may_24
A1: Location | B1: NBIP-NBIP Calls Revenue | C1: Fixed Calls Revenue | D1: Telekom Calls Revenue | E1: BMobile Calls Revenue | F1: Intl Calls Revenue | G1: A2P SMS Revenue | H1: Telekom SMS Revenue | I1: BMobile SMS Revenue | J1: Intl SMS Revenue | K1: Mobile Data Revenue | L1: Total
A2: NBIP_ANUHA | B2: 0 | C2: 0 | D2: 0 | E2: 0 | F2: 0 | G2: 0 | H2: 0 | I2: 0 | J2: 0 | K2: 0 | L2: =SUM(B2:K2) -> 0
A3: NBIP_Babasu | B3: 0 | C3: 0 | D3: 0 | E3: 0 | F3: 0 | G3: 0 | H3: 0 | I3: 0 | J3: 0 | K3: 0 | L3: =SUM(B3:K3) -> 0
A4: NBIP_Bambakani | B4: 0 | C4: 0 | D4: 0 | E4: 0 | F4: 0 | G4: 0 | H4: 0 | I4: 0 | J4: 0 | K4: 0 | L4: =SUM(B4:K4) -> 0
A5: NBIP_Baniata | B5: 0 | C5: 0 | D5: 0 | E5: 0 | F5: 0 | G5: 0 | H5: 0 | I5: 0 | J5: 0 | K5: 0 | L5: =SUM(B5:K5) -> 0
A6: NBIP_BELAGA | B6: 0 | C6: 0 | D6: 0 | E6: 0 | F6: 0 | G6: 0 | H6: 0 | I6: 0 | J6: 0 | K6: 0 | L6: =SUM(B6:K6) -> 0
A7: NBIP_BITILA/KUSINI | B7: 0 | C7: 0 | D7: 0 | E7: 0 | F7: 0 | G7: 0 | H7: 0 | I7: 0 | J7: 0 | K7: 0 | L7: =SUM(B7:K7) -> 0
A8: NBIP_BOLITEI | B8: 0 | C8: 0 | D8: 0 | E8: 0 | F8: 0 | G8: 0 | H8: 0 | I8: 0 | J8: 0 | K8: 0 | L8: =SUM(B8:K8) -> 0
A9: NBIP_Bubunughu | B9: 0 | C9: 0 | D9: 0 | E9: 0 | F9: 0 | G9: 0 | H9: 0 | I9: 0 | J9: 0 | K9: 0 | L9: =SUM(B9:K9) -> 0
A10: NBIP_CHIVOKA | B10: 0 | C10: 0 | D10: 0 | E10: 0 | F10: 0 | G10: 0 | H10: 0 | I10: 0 | J10: 0 | K10: 0 | L10: =SUM(B10:K10) -> 0
A11: NBIP_Dokudula | B11: 0 | C11: 0 | D11: 0 | E11: 0 | F11: 0 | G11: 0 | H11: 0 | I11: 0 | J11: 0 | K11: 0 | L11: =SUM(B11:K11) -> 0
A12: NBIP_Gesa | B12: 0 | C12: 0 | D12: 0 | E12: 0 | F12: 0 | G12: 0 | H12: 0 | I12: 0 | J12: 0 | K12: 0 | L12: =SUM(B12:K12) -> 0
A13: NBIP_Ghombua | B13: 0 | C13: 0 | D13: 0 | E13: 0 | F13: 0 | G13: 0 | H13: 0 | I13: 0 | J13: 0 | K13: 0 | L13: =SUM(B13:K13) -> 0
... A60: Total | B60: 2861.14 | C60: 100.3 | D60: 24631.94 | E60: 491.92 | F60: 129.79 | G60: 23.2 | H60: 741.9 | I60: 14.4 | J60: 49.5 | K60: 56857.73 | L60: =SUM(B60:K60) -> 85901.82

Sheet jun_24
A1: Location | B1: NBIP-NBIP Calls Revenue | C1: Fixed Calls Revenue | D1: Telekom Calls Revenue | E1: BMobile Calls Revenue | F1: Intl Calls Revenue | G1: A2P SMS Revenue | H1: Telekom SMS Revenue | I1: BMobile SMS Revenue | J1: Intl SMS Revenue | K1: Mobile Data Revenue | L1: Total
A2: NBIP_ANUHA | B2: 0 | C2: 0 | D2: 0 | E2: 0 | F2: 0 | G2: 0 | H2: 0 | I2: 0 | J2: 0 | K2: 0 | L2: =SUM(B2:K2) -> 0
A3: NBIP_Babasu | B3: 0 | C3: 0 | D3: 0 | E3: 0 | F3: 0 | G3: 0 | H3: 0 | I3: 0 | J3: 0 | K3: 0 | L3: =SUM(B3:K3) -> 0
A4: NBIP_Bambakani | B4: 0 | C4: 0 | D4: 0 | E4: 0 | F4: 0 | G4: 0 | H4: 0 | I4: 0 | J4: 0 | K4: 0 | L4: =SUM(B4:K4) -> 0
A5: NBIP_Baniata | B5: 0 | C5: 0 | D5: 0 | E5: 0 | F5: 0 | G5: 0 | H5: 0 | I5: 0 | J5: 0 | K5: 0 | L5: =SUM(B5:K5) -> 0
A6: NBIP_BELAGA | B6: 0 | C6: 0 | D6: 0 | E6: 0 | F6: 0 | G6: 0 | H6: 0 | I6: 0 | J6: 0 | K6: 0 | L6: =SUM(B6:K6) -> 0
A7: NBIP_BITILA/KUSINI | B7: 0 | C7: 0 | D7: 0 | E7: 0 | F7: 0 | G7: 0 | H7: 0 | I7: 0 | J7: 0 | K7: 0 | L7: =SUM(B7:K7) -> 0
A8: NBIP_BOLITEI | B8: 0 | C8: 0 | D8: 0 | E8: 0 | F8: 0 | G8: 0 | H8: 0 | I8: 0 | J8: 0 | K8: 0 | L8: =SUM(B8:K8) -> 0
A9: NBIP_Bubunughu | B9: 0 | C9: 0 | D9: 0 | E9: 0 | F9: 0 | G9: 0 | H9: 0 | I9: 0 | J9: 0 | K9: 0 | L9: =SUM(B9:K9) -> 0
A10: NBIP_CHIVOKA | B10: 0 | C10: 0 | D10: 0 | E10: 0 | F10: 0 | G10: 0 | H10: 0 | I10: 0 | J10: 0 | K10: 0 | L10: =SUM(B10:K10) -> 0
A11: NBIP_Dokudula | B11: 0 | C11: 0 | D11: 0 | E11: 0 | F11: 0 | G11: 0 | H11: 0 | I11: 0 | J11: 0 | K11: 0 | L11: =SUM(B11:K11) -> 0
A12: NBIP_Gesa | B12: 0 | C12: 0 | D12: 0 | E12: 0 | F12: 0 | G12: 0 | H12: 0 | I12: 0 | J12: 0 | K12: 0 | L12: =SUM(B12:K12) -> 0
A13: NBIP_Ghombua | B13: 0 | C13: 0 | D13: 0 | E13: 0 | F13: 0 | G13: 0 | H13: 0 | I13: 0 | J13: 0 | K13: 0 | L13: =SUM(B13:K13) -> 0
... A60: Total | B60: 4479.01 | C60: 100.63 | D60: 29416.83 | E60: 579.83 | F60: 86.29 | G60: 51.4 | H60: 753.2 | I60: 19.2 | J60: 53.7 | K60: 81355.61 | L60: =SUM(B60:K60) -> 116895.7

Sheet jul_24
A1: Location | B1: NBIP-NBIP Calls Revenue | C1: Fixed Calls Revenue | D1: Telekom Calls Revenue | E1: BMobile Calls Revenue | F1: Intl Calls Revenue | G1: A2P SMS Revenue | H1: Telekom SMS Revenue | I1: BMobile SMS Revenue | J1: Intl SMS Revenue | K1: Mobile Data Revenue | L1: Total
A2: NBIP_ANUHA | B2: 0 | C2: 0 | D2: 0 | E2: 0 | F2: 0 | G2: 0 | H2: 0 | I2: 0 | J2: 0 | K2: 0 | L2: =SUM(B2:K2) -> 0
A3: NBIP_Babasu | B3: 0 | C3: 0 | D3: 0 | E3: 0 | F3: 0 | G3: 0 | H3: 0 | I3: 0 | J3: 0 | K3: 0 | L3: =SUM(B3:K3) -> 0
A4: NBIP_Bambakani | B4: 0 | C4: 0 | D4: 0 | E4: 0 | F4: 0 | G4: 0 | H4: 0 | I4: 0 | J4: 0 | K4: 0 | L4: =SUM(B4:K4) -> 0
A5: NBIP_Baniata | B5: 0 | C5: 0 | D5: 0 | E5: 0 | F5: 0 | G5: 0 | H5: 0 | I5: 0 | J5: 0 | K5: 0 | L5: =SUM(B5:K5) -> 0
A6: NBIP_BELAGA | B6: 0 | C6: 0 | D6: 0 | E6: 0 | F6: 0 | G6: 0 | H6: 0 | I6: 0 | J6: 0 | K6: 0 | L6: =SUM(B6:K6) -> 0
A7: NBIP_BITILA/KUSINI | B7: 0 | C7: 0 | D7: 0 | E7: 0 | F7: 0 | G7: 0 | H7: 0 | I7: 0 | J7: 0 | K7: 0 | L7: =SUM(B7:K7) -> 0
A8: NBIP_BOLITEI | B8: 0 | C8: 0 | D8: 0 | E8: 0 | F8: 0 | G8: 0 | H8: 0 | I8: 0 | J8: 0 | K8: 0 | L8: =SUM(B8:K8) -> 0
A9: NBIP_Bubunughu | B9: 0 | C9: 0 | D9: 0 | E9: 0 | F9: 0 | G9: 0 | H9: 0 | I9: 0 | J9: 0 | K9: 0 | L9: =SUM(B9:K9) -> 0
A10: NBIP_CHIVOKA | B10: 0 | C10: 0 | D10: 0 | E10: 0 | F10: 0 | G10: 0 | H10: 0 | I10: 0 | J10: 0 | K10: 0 | L10: =SUM(B10:K10) -> 0
A11: NBIP_Dokudula | B11: 0 | C11: 0 | D11: 0 | E11: 0 | F11: 0 | G11: 0 | H11: 0 | I11: 0 | J11: 0 | K11: 0 | L11: =SUM(B11:K11) -> 0
A12: NBIP_Gesa | B12: 0 | C12: 0 | D12: 0 | E12: 0 | F12: 0 | G12: 0 | H12: 0 | I12: 0 | J12: 0 | K12: 0 | L12: =SUM(B12:K12) -> 0
A13: NBIP_Ghombua | B13: 887.82 | C13: 7.97 | D13: 4939.19 | E13: 161.22 | F13: 19.58 | G13: 2.9 | H13: 82.6 | I13: 3.1 | J13: 6.9 | K13: 8155.97 | L13: =SUM(B13:K13) -> 14267.25
... A60: Total | B60: 7143.2 | C60: 178.3 | D60: 47649.67 | E60: 1077.43 | F60: 99.38 | G60: 47 | H60: 1351.7 | I60: 37 | J60: 41 | K60: 102859.37 | L60: =SUM(B60:K60) -> 160484.05

Sheet aug_24
A1: Location | B1: NBIP-NBIP Calls Revenue | C1: Fixed Calls Revenue | D1: Telekom Calls Revenue | E1: BMobile Calls Revenue | F1: Intl Calls Revenue | G1: A2P SMS Revenue | H1: Telekom SMS Revenue | I1: BMobile SMS Revenue | J1: Intl SMS Revenue | K1: Mobile Data Revenue | L1: Total
A2: NBIP_ANUHA | B2: 0 | C2: 0 | D2: 0 | E2: 0 | F2: 0 | G2: 0 | H2: 0 | I2: 0 | J2: 0 | K2: 0 | L2: =SUM(B2:K2) -> 0
A3: NBIP_Babasu | B3: 0 | C3: 0 | D3: 0 | E3: 0 | F3: 0 | G3: 0 | H3: 0 | I3: 0 | J3: 0 | K3: 0 | L3: =SUM(B3:K3) -> 0
A4: NBIP_Bambakani | B4: 0 | C4: 0 | D4: 0 | E4: 0 | F4: 0 | G4: 0 | H4: 0 | I4: 0 | J4: 0 | K4: 0 | L4: =SUM(B4:K4) -> 0
A5: NBIP_Baniata | B5: 0 | C5: 0 | D5: 0 | E5: 0 | F5: 0 | G5: 0 | H5: 0 | I5: 0 | J5: 0 | K5: 0 | L5: =SUM(B5:K5) -> 0
A6: NBIP_BELAGA | B6: 0 | C6: 0 | D6: 0 | E6: 0 | F6: 0 | G6: 0 | H6: 0 | I6: 0 | J6: 0 | K6: 0 | L6: =SUM(B6:K6) -> 0
A7: NBIP_BITILA/KUSINI | B7: 0 | C7: 0 | D7: 0 | E7: 0 | F7: 0 | G7: 0 | H7: 0 | I7: 0 | J7: 0 | K7: 0 | L7: =SUM(B7:K7) -> 0
A8: NBIP_BOLITEI | B8: 0 | C8: 0 | D8: 0 | E8: 0 | F8: 0 | G8: 0 | H8: 0 | I8: 0 | J8: 0 | K8: 0 | L8: =SUM(B8:K8) -> 0
A9: NBIP_Bubunughu | B9: 0 | C9: 0 | D9: 0 | E9: 0 | F9: 0 | G9: 0 | H9: 0 | I9: 0 | J9: 0 | K9: 0 | L9: =SUM(B9:K9) -> 0
A10: NBIP_CHIVOKA | B10: 0 | C10: 0 | D10: 0 | E10: 0 | F10: 0 | G10: 0 | H10: 0 | I10: 0 | J10: 0 | K10: 0 | L10: =SUM(B10:K10) -> 0
A11: NBIP_Dokudula | B11: 0 | C11: 0 | D11: 0 | E11: 0 | F11: 0 | G11: 0 | H11: 0 | I11: 0 | J11: 0 | K11: 0 | L11: =SUM(B11:K11) -> 0
A12: NBIP_Gesa | B12: 0 | C12: 0 | D12: 0 | E12: 0 | F12: 0 | G12: 0 | H12: 0 | I12: 0 | J12: 0 | K12: 0 | L12: =SUM(B12:K12) -> 0
A13: NBIP_Ghombua | B13: 10024.56 | C13: 12.03 | D13: 342.92 | E13: 283.46 | F13: 26.88 | G13: 4.9 | H13: 129.9 | I13: 3.2 | J13: 3.5 | K13: 11844.46 | L13: =SUM(B13:K13) -> 22675.81
... A60: Total | B60: 64493.83 | C60: 182.48 | D60: 2446.51 | E60: 1551.52 | F60: 166.89 | G60: 47.1 | H60: 1420.3 | I60: 79 | J60: 49.3 | K60: 103047.9 | L60: =SUM(B60:K60) -> 173484.83

Sheet sep_24
A1: Location | B1: NBIP-NBIP Calls Revenue | C1: Fixed Calls Revenue | D1: Telekom Calls Revenue | E1: BMobile Calls Revenue | F1: Intl Calls Revenue | G1: A2P SMS Revenue | H1: Telekom SMS Revenue | I1: BMobile SMS Revenue | J1: Intl SMS Revenue | K1: Mobile Data Revenue | L1: Total
A2: NBIP_ANUHA | B2: 0 | C2: 0 | D2: 0 | E2: 0 | F2: 0 | G2: 0 | H2: 0 | I2: 0 | J2: 0 | K2: 0 | L2: =SUM(B2:K2) -> 0
A3: NBIP_Babasu | B3: 152.36 | C3: 0.73 | D3: 0.3 | E3: 0 | F3: 0.02 | G3: 0 | H3: 26.1 | I3: 0 | J3: 0.1 | K3: 202.86 | L3: =SUM(B3:K3) -> 382.47
A4: NBIP_Bambakani | B4: 0 | C4: 0 | D4: 0 | E4: 0 | F4: 0 | G4: 0 | H4: 0 | I4: 0 | J4: 0 | K4: 0 | L4: =SUM(B4:K4) -> 0
A5: NBIP_Baniata | B5: 0 | C5: 0 | D5: 0 | E5: 0 | F5: 0 | G5: 0 | H5: 0 | I5: 0 | J5: 0 | K5: 0 | L5: =SUM(B5:K5) -> 0
A6: NBIP_BELAGA | B6: 0 | C6: 0 | D6: 0 | E6: 0 | F6: 0 | G6: 0 | H6: 0 | I6: 0 | J6: 0 | K6: 0 | L6: =SUM(B6:K6) -> 0
A7: NBIP_BITILA/KUSINI | B7: 0 | C7: 0 | D7: 0 | E7: 0 | F7: 0 | G7: 0 | H7: 0 | I7: 0 | J7: 0 | K7: 0 | L7: =SUM(B7:K7) -> 0
A8: NBIP_BOLITEI | B8: 0 | C8: 0 | D8: 0 | E8: 0 | F8: 0 | G8: 0 | H8: 0 | I8: 0 | J8: 0 | K8: 0 | L8: =SUM(B8:K8) -> 0
A9: NBIP_Bubunughu | B9: 7280.62 | C9: 19.32 | D9: 154.04 | E9: 99.41 | F9: 2.1 | G9: 8.3 | H9: 69.8 | I9: 3.5 | J9: 1.6 | K9: 5506.61 | L9: =SUM(B9:K9) -> 13145.3
A10: NBIP_CHIVOKA | B10: 0 | C10: 0 | D10: 0 | E10: 0 | F10: 0 | G10: 0 | H10: 0 | I10: 0 | J10: 0 | K10: 0 | L10: =SUM(B10:K10) -> 0
A11: NBIP_Dokudula | B11: 0 | C11: 0 | D11: 0 | E11: 0 | F11: 0 | G11: 0 | H11: 0 | I11: 0 | J11: 0 | K11: 0 | L11: =SUM(B11:K11) -> 0
A12: NBIP_Gesa | B12: 7738.77 | C12: 24.2 | D12: 288.46 | E12: 178.87 | F12: 1.15 | G12: 3.1 | H12: 68.7 | I12: 31.8 | J12: 5.6 | K12: 11095.1 | L12: =SUM(B12:K12) -> 19435.75
A13: NBIP_Ghombua | B13: 9550.86 | C13: 17.54 | D13: 220.12 | E13: 194.07 | F13: 4.48 | G13: 1.9 | H13: 324.2 | I13: 8.9 | J13: 1.5 | K13: 11910.36 | L13: =SUM(B13:K13) -> 22233.93
... A60: Total | B60: 80323.24 | C60: 225.1 | D60: 2785.61 | E60: 1475.1 | F60: 41.31 | G60: 80.8 | H60: 1966 | I60: 144.7 | J60: 40.2 | K60: 130827.52 | L60: =SUM(B60:K60) -> 217909.58

Sheet oct_24
A1: Location | B1: NBIP-NBIP Calls Revenue | C1: Fixed Calls Revenue | D1: Telekom Calls Revenue | E1: BMobile Calls Revenue | F1: Intl Calls Revenue | G1: A2P SMS Revenue | H1: Telekom SMS Revenue | I1: BMobile SMS Revenue | J1: Intl SMS Revenue | K1: Mobile Data Revenue | L1: Total
A2: NBIP_ANUHA | B2: 0 | C2: 0 | D2: 0 | E2: 0 | F2: 0 | G2: 0 | H2: 0 | I2: 0 | J2: 0 | K2: 0 | L2: =SUM(B2:K2) -> 0
A3: NBIP_Babasu | B3: 1721.75 | C3: 8.32 | D3: 105.14 | E3: 8.37 | F3: 9.56 | G3: 0.2 | H3: 96.7 | I3: 14.7 | J3: 0.4 | K3: 2046.22 | L3: =SUM(B3:K3) -> 4011.36
A4: NBIP_Bambakani | B4: 0 | C4: 0 | D4: 0 | E4: 0 | F4: 0 | G4: 0 | H4: 0 | I4: 0 | J4: 0 | K4: 0 | L4: =SUM(B4:K4) -> 0
A5: NBIP_Baniata | B5: 0 | C5: 0 | D5: 0 | E5: 0 | F5: 0 | G5: 0 | H5: 0 | I5: 0 | J5: 0 | K5: 0 | L5: =SUM(B5:K5) -> 0
A6: NBIP_BELAGA | B6: 0 | C6: 0 | D6: 0 | E6: 0 | F6: 0 | G6: 0 | H6: 0 | I6: 0 | J6: 0 | K6: 0 | L6: =SUM(B6:K6) -> 0
A7: NBIP_BITILA/KUSINI | B7: 0 | C7: 0 | D7: 0 | E7: 0 | F7: 0 | G7: 0 | H7: 0 | I7: 0 | J7: 0 | K7: 0 | L7: =SUM(B7:K7) -> 0
A8: NBIP_BOLITEI | B8: 0 | C8: 0 | D8: 0 | E8: 0 | F8: 0 | G8: 0 | H8: 0 | I8: 0 | J8: 0 | K8: 0 | L8: =SUM(B8:K8) -> 0
A9: NBIP_Bubunughu | B9: 8494.72 | C9: 15.9 | D9: 128.47 | E9: 85.35 | F9: 2.51 | G9: 7.2 | H9: 81.8 | I9: 12.3 | J9: 0.5 | K9: 5757.83 | L9: =SUM(B9:K9) -> 14586.58
A10: NBIP_CHIVOKA | B10: 0 | C10: 0 | D10: 0 | E10: 0 | F10: 0 | G10: 0 | H10: 0 | I10: 0 | J10: 0 | K10: 0 | L10: =SUM(B10:K10) -> 0
A11: NBIP_Dokudula | B11: 0 | C11: 0 | D11: 0 | E11: 0 | F11: 0 | G11: 0 | H11: 0 | I11: 0 | J11: 0 | K11: 0 | L11: =SUM(B11:K11) -> 0
A12: NBIP_Gesa | B12: 8761.66 | C12: 18.03 | D12: 380.2 | E12: 165.99 | F12: 1.4 | G12: 4.8 | H12: 114.3 | I12: 24.4 | J12: 2.8 | K12: 12825.67 | L12: =SUM(B12:K12) -> 22299.25
A13: NBIP_Ghombua | B13: 9823.38 | C13: 13.21 | D13: 292.91 | E13: 126.35 | F13: 40.54 | G13: 1.5 | H13: 88.5 | I13: 3 | J13: 1.2 | K13: 11076.85 | L13: =SUM(B13:K13) -> 21467.44
... A60: Total | B60: 115471.89 | C60: 299.37 | D60: 4673.56 | E60: 1675.84 | F60: 224.99 | G60: 368.3 | H60: 1987.4 | I60: 192.8 | J60: 28.6 | K60: 157366.21 | L60: =SUM(B60:K60) -> 282288.96

Sheet nov_24
A1: Location | B1: NBIP-NBIP Calls Revenue | C1: Fixed Calls Revenue | D1: Telekom Calls Revenue | E1: BMobile Calls Revenue | F1: Intl Calls Revenue | G1: A2P SMS Revenue | H1: Telekom SMS Revenue | I1: BMobile SMS Revenue | J1: Intl SMS Revenue | K1: Mobile Data Revenue | L1: Total
A2: NBIP_ANUHA | B2: 0 | C2: 0 | D2: 0 | E2: 0 | F2: 0 | G2: 0 | H2: 0 | I2: 0 | J2: 0 | K2: 0 | L2: =SUM(B2:K2) -> 0
A3: NBIP_Babasu | B3: 1879.56 | C3: 6.73 | D3: 149.57 | E3: 16.7 | F3: 3.38 | G3: 3.3 | H3: 70.4 | I3: 0.2 | J3: 0.5 | K3: 1102.35 | L3: =SUM(B3:K3) -> 3232.69
A4: NBIP_Bambakani | B4: 0 | C4: 0 | D4: 0 | E4: 0 | F4: 0 | G4: 0 | H4: 0 | I4: 0 | J4: 0 | K4: 0 | L4: =SUM(B4:K4) -> 0
A5: NBIP_Baniata | B5: 0 | C5: 0 | D5: 0 | E5: 0 | F5: 0 | G5: 0 | H5: 0 | I5: 0 | J5: 0 | K5: 0 | L5: =SUM(B5:K5) -> 0
A6: NBIP_BELAGA | B6: 0 | C6: 0 | D6: 0 | E6: 0 | F6: 0 | G6: 0 | H6: 0 | I6: 0 | J6: 0 | K6: 0 | L6: =SUM(B6:K6) -> 0
A7: NBIP_BITILA/KUSINI | B7: 0 | C7: 0 | D7: 0 | E7: 0 | F7: 0 | G7: 0 | H7: 0 | I7: 0 | J7: 0 | K7: 0 | L7: =SUM(B7:K7) -> 0
A8: NBIP_BOLITEI | B8: 0 | C8: 0 | D8: 0 | E8: 0 | F8: 0 | G8: 0 | H8: 0 | I8: 0 | J8: 0 | K8: 0 | L8: =SUM(B8:K8) -> 0
A9: NBIP_Bubunughu | B9: 8557.76 | C9: 12.61 | D9: 200.61 | E9: 114.8 | F9: 3.52 | G9: 1.7 | H9: 55.4 | I9: 1.8 | J9: 2.5 | K9: 6722.74 | L9: =SUM(B9:K9) -> 15673.44
A10: NBIP_CHIVOKA | B10: 0 | C10: 0 | D10: 0 | E10: 0 | F10: 0 | G10: 0 | H10: 0 | I10: 0 | J10: 0 | K10: 0 | L10: =SUM(B10:K10) -> 0
A11: NBIP_Dokudula | B11: 0 | C11: 0 | D11: 0 | E11: 0 | F11: 0 | G11: 0 | H11: 0 | I11: 0 | J11: 0 | K11: 0 | L11: =SUM(B11:K11) -> 0
A12: NBIP_Gesa | B12: 9413.2 | C12: 36.24 | D12: 373.92 | E12: 150.66 | F12: 1.25 | G12: 4.5 | H12: 89.5 | I12: 6.3 | J12: 2.2 | K12: 12767.61 | L12: =SUM(B12:K12) -> 22845.38
A13: NBIP_Ghombua | B13: 10601.33 | C13: 15.49 | D13: 337.96 | E13: 161.61 | F13: 9.43 | G13: 1.5 | H13: 105.6 | I13: 1.3 | J13: 1.8 | K13: 10958.52 | L13: =SUM(B13:K13) -> 22194.54
... A60: Total | B60: 127573.75 | C60: 383.35 | D60: 5915.46 | E60: 2010.46 | F60: 184.72 | G60: 309.7 | H60: 2483.8 | I60: 40.2 | J60: 42.8 | K60: 166158.8 | L60: =SUM(B60:K60) -> 305103.04

Sheet dec_24
A1: Location | B1: NBIP-NBIP Calls Revenue | C1: Fixed Calls Revenue | D1: Telekom Calls Revenue | E1: BMobile Calls Revenue | F1: Intl Calls Revenue | G1: A2P SMS Revenue | H1: Telekom SMS Revenue | I1: BMobile SMS Revenue | J1: Intl SMS Revenue | K1: Mobile Data Revenue | L1: Total
A2: NBIP_ANUHA | B2: 0 | C2: 11.97 | D2: 4157.02 | E2: 59.3 | F2: 2.1 | G2: 0.7 | H2: 40.4 | I2: 0.7 | J2: 4 | K2: 3424.75 | L2: =SUM(B2:K2) -> 7700.94
A3: NBIP_Babasu | B3: 368.75 | C3: 5.4 | D3: 2138.09 | E3: 9.84 | F3: 0.88 | G3: 3 | H3: 54 | I3: 0 | J3: 1 | K3: 1656.21 | L3: =SUM(B3:K3) -> 4237.17
A4: NBIP_Bambakani | B4: 0 | C4: 0 | D4: 0 | E4: 0 | F4: 0 | G4: 0 | H4: 0 | I4: 0 | J4: 0 | K4: 0 | L4: =SUM(B4:K4) -> 0
A5: NBIP_Baniata | B5: 0 | C5: 0 | D5: 0 | E5: 0 | F5: 0 | G5: 0 | H5: 0 | I5: 0 | J5: 0 | K5: 0 | L5: =SUM(B5:K5) -> 0
A6: NBIP_BELAGA | B6: 699 | C6: 9.01 | D6: 2583.34 | E6: 120.83 | F6: 0.85 | G6: 0.5 | H6: 83.9 | I6: 1.9 | J6: 6.1 | K6: 3629.08 | L6: =SUM(B6:K6) -> 7134.51
A7: NBIP_BITILA/KUSINI | B7: 59.11 | C7: 0.44 | D7: 1305.01 | E7: 43.15 | F7: 73.43 | G7: 0.1 | H7: 31.3 | I7: 0.7 | J7: 0.2 | K7: 2198.61 | L7: =SUM(B7:K7) -> 3712.05
A8: NBIP_BOLITEI | B8: 203.48 | C8: 1.98 | D8: 3018.03 | E8: 11.22 | F8: 7.2 | G8: 1.1 | H8: 64 | I8: 0 | J8: 4.4 | K8: 2862.76 | L8: =SUM(B8:K8) -> 6174.17
A9: NBIP_Bubunughu | B9: 2594.94 | C9: 9.88 | D9: 6707.99 | E9: 116.17 | F9: 1.52 | G9: 6.7 | H9: 69 | I9: 2.9 | J9: 3.6 | K9: 7396.93 | L9: =SUM(B9:K9) -> 16909.63
A10: NBIP_CHIVOKA | B10: 0 | C10: 0 | D10: 0 | E10: 0 | F10: 0 | G10: 0 | H10: 0 | I10: 0 | J10: 0 | K10: 0 | L10: =SUM(B10:K10) -> 0
A11: NBIP_Dokudula | B11: 0 | C11: 0 | D11: 0 | E11: 0 | F11: 0 | G11: 0 | H11: 0 | I11: 0 | J11: 0 | K11: 0 | L11: =SUM(B11:K11) -> 0
A12: NBIP_Gesa | B12: 2522.31 | C12: 12.13 | D12: 7462.86 | E12: 66.78 | F12: 3.67 | G12: 5 | H12: 135.5 | I12: 2.4 | J12: 5.2 | K12: 11531.2 | L12: =SUM(B12:K12) -> 21747.05
A13: NBIP_Ghombua | B13: 3369.48 | C13: 11.68 | D13: 7435.28 | E13: 128.23 | F13: 24.26 | G13: 1.4 | H13: 195 | I13: 0.7 | J13: 6.8 | K13: 11051.97 | L13: =SUM(B13:K13) -> 22224.8
... A60: Total | B60: 34326.29 | C60: 348.15 | D60: 139950.69 | E60: 1678.46 | F60: 477.75 | G60: 157.4 | H60: 3730.1 | I60: 30.9 | J60: 94.4 | K60: 181823.57 | L60: =SUM(B60:K60) -> 362617.71

Sheet jan_25
A1: Location | B1: NBIP-NBIP Calls Revenue | C1: Fixed Calls Revenue | D1: Telekom Calls Revenue | E1: BMobile Calls Revenue | F1: Intl Calls Revenue | G1: A2P SMS Revenue | H1: Telekom SMS Revenue | I1: BMobile SMS Revenue | J1: Intl SMS Revenue | K1: Mobile Data Revenue | L1: Total
A2: NBIP_ANUHA | B2: 2144.38 | C2: 26.49 | D2: 6588.26 | E2: 82.92 | F2: 9.55 | G2: 2.7 | H2: 69.8 | I2: 0.6 | J2: 3.4 | K2: 8231.3 | L2: =SUM(B2:K2) -> 17159.4
A3: NBIP_Babasu | B3: 321.49 | C3: 8.68 | D3: 1939.99 | E3: 14.71 | F3: 0.93 | G3: 3.4 | H3: 49 | I3: 0.1 | J3: 0.7 | K3: 2610.95 | L3: =SUM(B3:K3) -> 4949.95
A4: NBIP_Bambakani | B4: 0 | C4: 0 | D4: 0 | E4: 0 | F4: 0 | G4: 0 | H4: 0 | I4: 0 | J4: 0 | K4: 0 | L4: =SUM(B4:K4) -> 0
A5: NBIP_Baniata | B5: 0 | C5: 0 | D5: 0 | E5: 0 | F5: 0 | G5: 0 | H5: 0 | I5: 0 | J5: 0 | K5: 0 | L5: =SUM(B5:K5) -> 0
A6: NBIP_BELAGA | B6: 2402.15 | C6: 19.91 | D6: 7556.11 | E6: 172.98 | F6: 17.96 | G6: 3.1 | H6: 280.5 | I6: 2.4 | J6: 9.4 | K6: 10305.22 | L6: =SUM(B6:K6) -> 20769.73
A7: NBIP_BITILA/KUSINI | B7: 244.99 | C7: 13.07 | D7: 2343.58 | E7: 28.25 | F7: 42.75 | G7: 0.3 | H7: 52.9 | I7: 1.3 | J7: 3 | K7: 5520.49 | L7: =SUM(B7:K7) -> 8250.63
A8: NBIP_BOLITEI | B8: 617.44 | C8: 33.01 | D8: 8247.62 | E8: 217.71 | F8: 7.58 | G8: 1.9 | H8: 186 | I8: 1.8 | J8: 2.8 | K8: 9085.45 | L8: =SUM(B8:K8) -> 18401.31
A9: NBIP_Bubunughu | B9: 2610.08 | C9: 9.35 | D9: 6301.28 | E9: 91.77 | F9: 1.76 | G9: 2.8 | H9: 95.4 | I9: 0.6 | J9: 1.7 | K9: 7546.32 | L9: =SUM(B9:K9) -> 16661.06
A10: NBIP_CHIVOKA | B10: 0 | C10: 0 | D10: 0 | E10: 0 | F10: 0 | G10: 0 | H10: 0 | I10: 0 | J10: 0 | K10: 0 | L10: =SUM(B10:K10) -> 0
A11: NBIP_Dokudula | B11: 0 | C11: 0 | D11: 0 | E11: 0 | F11: 0 | G11: 0 | H11: 0 | I11: 0 | J11: 0 | K11: 0 | L11: =SUM(B11:K11) -> 0
A12: NBIP_Gesa | B12: 2451.65 | C12: 11.8 | D12: 7301.62 | E12: 111.74 | F12: 1.97 | G12: 7.5 | H12: 185.2 | I12: 1.9 | J12: 3.8 | K12: 11658.38 | L12: =SUM(B12:K12) -> 21735.56
A13: NBIP_Ghombua | B13: 4653.51 | C13: 5.25 | D13: 6824.43 | E13: 88.06 | F13: 5.65 | G13: 3 | H13: 93.5 | I13: 0.9 | J13: 4.3 | K13: 14608.45 | L13: =SUM(B13:K13) -> 26287.05
... A60: Total | B60: 45763.18 | C60: 471.49 | D60: 156703.07 | E60: 2330.7 | F60: 263.12 | G60: 117.5 | H60: 5444.6 | I60: 24.5 | J60: 84.7 | K60: 238936.99 | L60: =SUM(B60:K60) -> 450139.85

Sheet feb_25
A1: Location | B1: NBIP-NBIP Calls Revenue | C1: Fixed Calls Revenue | D1: Telekom Calls Revenue | E1: BMobile Calls Revenue | F1: Intl Calls Revenue | G1: A2P SMS Revenue | H1: Telekom SMS Revenue | I1: BMobile SMS Revenue | J1: Intl SMS Revenue | K1: Mobile Data Revenue | L1: Total
A2: NBIP_ANUHA | B2: 1510.9 | C2: 15.34 | D2: 6250.33 | E2: 79.64 | F2: 6.36 | G2: 3 | H2: 83.6 | I2: 0.5 | J2: 1.8 | K2: 3683.12 | L2: =SUM(B2:K2) -> 11634.59
A3: NBIP_Babasu | B3: 200.89 | C3: 6.68 | D3: 1534.88 | E3: 14.07 | F3: 0.81 | G3: 2.3 | H3: 34 | I3: 0 | J3: 0 | K3: 1050.54 | L3: =SUM(B3:K3) -> 2844.17
A4: NBIP_Bambakani | B4: 0 | C4: 0 | D4: 0 | E4: 0 | F4: 0 | G4: 0 | H4: 0 | I4: 0 | J4: 0 | K4: 0 | L4: =SUM(B4:K4) -> 0
A5: NBIP_Baniata | B5: 0 | C5: 0 | D5: 0 | E5: 0 | F5: 0 | G5: 0 | H5: 0 | I5: 0 | J5: 0 | K5: 0 | L5: =SUM(B5:K5) -> 0
A6: NBIP_BELAGA | B6: 1195.08 | C6: 11.25 | D6: 6815.48 | E6: 125.92 | F6: 19.78 | G6: 2 | H6: 105.4 | I6: 1.7 | J6: 4.5 | K6: 3758.99 | L6: =SUM(B6:K6) -> 12040.1
A7: NBIP_BITILA/KUSINI | B7: 200.53 | C7: 4.84 | D7: 2128.18 | E7: 27.44 | F7: 81.73 | G7: 0.9 | H7: 62.6 | I7: 0.2 | J7: 1.6 | K7: 5067.09 | L7: =SUM(B7:K7) -> 7575.11
A8: NBIP_BOLITEI | B8: 690.1 | C8: 33.07 | D8: 7456.23 | E8: 26.7 | F8: 21.38 | G8: 0.7 | H8: 162.3 | I8: 3.8 | J8: 1 | K8: 5214.78 | L8: =SUM(B8:K8) -> 13610.06
A9: NBIP_Bubunughu | B9: 2410.51 | C9: 5.15 | D9: 5843.99 | E9: 39.11 | F9: 0.68 | G9: 2.1 | H9: 62.2 | I9: 0.6 | J9: 3.7 | K9: 6090.23 | L9: =SUM(B9:K9) -> 14458.27
A10: NBIP_CHIVOKA | B10: 0 | C10: 0 | D10: 0 | E10: 0 | F10: 0 | G10: 0 | H10: 0 | I10: 0 | J10: 0 | K10: 0 | L10: =SUM(B10:K10) -> 0
A11: NBIP_Dokudula | B11: 0 | C11: 0 | D11: 0 | E11: 0 | F11: 0 | G11: 0 | H11: 0 | I11: 0 | J11: 0 | K11: 0 | L11: =SUM(B11:K11) -> 0
A12: NBIP_Gesa | B12: 1568.09 | C12: 19.99 | D12: 7202.34 | E12: 47.12 | F12: 1.62 | G12: 3.7 | H12: 113.4 | I12: 1.1 | J12: 3.7 | K12: 10442.96 | L12: =SUM(B12:K12) -> 19404.02
A13: NBIP_Ghombua | B13: 3003.84 | C13: 6 | D13: 5129.97 | E13: 59.62 | F13: 22.83 | G13: 0.4 | H13: 73.8 | I13: 0.2 | J13: 3.3 | K13: 8183.97 | L13: =SUM(B13:K13) -> 16483.93
... A60: Total | B60: 33937.76 | C60: 397.33 | D60: 139127.28 | E60: 1261.8 | F60: 441.41 | G60: 130.1 | H60: 3897 | I60: 20.9 | J60: 58.7 | K60: 171821.33 | L60: =SUM(B60:K60) -> 351093.61

Sheet mar_25
A1: Location | B1: NBIP-NBIP Calls Revenue | C1: Fixed Calls Revenue | D1: Telekom Calls Revenue | E1: BMobile Calls Revenue | F1: Intl Calls Revenue | G1: A2P SMS Revenue | H1: Telekom SMS Revenue | I1: BMobile SMS Revenue | J1: Intl SMS Revenue | K1: Mobile Data Revenue | L1: Total
A2: NBIP_ANUHA | B2: 1815.23 | C2: 21.32 | D2: 7126.71 | E2: 29.43 | F2: 8.82 | G2: 0.7 | H2: 45.4 | I2: 0.8 | J2: 0.1 | K2: 3491.79 | L2: =SUM(B2:K2) -> 12540.3
A3: NBIP_Babasu | B3: 85.11 | C3: 1.97 | D3: 1530.73 | E3: 24.32 | F3: 0.03 | G3: 4.8 | H3: 9.9 | I3: 0 | J3: 3.7 | K3: 764.82 | L3: =SUM(B3:K3) -> 2425.38
A4: NBIP_Bambakani | B4: 0 | C4: 0 | D4: 0 | E4: 0 | F4: 0 | G4: 0 | H4: 0 | I4: 0 | J4: 0 | K4: 0 | L4: =SUM(B4:K4) -> 0
A5: NBIP_Baniata | B5: 0 | C5: 0 | D5: 0 | E5: 0 | F5: 0 | G5: 0 | H5: 0 | I5: 0 | J5: 0 | K5: 0 | L5: =SUM(B5:K5) -> 0
A6: NBIP_BELAGA | B6: 1195.29 | C6: 13.81 | D6: 7622.36 | E6: 187.13 | F6: 3.82 | G6: 3.7 | H6: 175.4 | I6: 1.3 | J6: 1 | K6: 4074.09 | L6: =SUM(B6:K6) -> 13277.9
A7: NBIP_BITILA/KUSINI | B7: 195.3 | C7: 6.98 | D7: 2874.53 | E7: 64.27 | F7: 130.13 | G7: 0.3 | H7: 63.7 | I7: 2.1 | J7: 2.2 | K7: 5674.23 | L7: =SUM(B7:K7) -> 9013.74
A8: NBIP_BOLITEI | B8: 968.4 | C8: 35.85 | D8: 9400.85 | E8: 37.58 | F8: 13.61 | G8: 0.6 | H8: 191.6 | I8: 1.7 | J8: 1.3 | K8: 6308.76 | L8: =SUM(B8:K8) -> 16960.25
A9: NBIP_Bubunughu | B9: 3406.18 | C9: 17.09 | D9: 6595.86 | E9: 42.41 | F9: 1.45 | G9: 3 | H9: 75.4 | I9: 1.8 | J9: 12.3 | K9: 6774.4 | L9: =SUM(B9:K9) -> 16929.89
A10: NBIP_CHIVOKA | B10: 0 | C10: 0 | D10: 0 | E10: 0 | F10: 0 | G10: 0 | H10: 0 | I10: 0 | J10: 0 | K10: 0 | L10: =SUM(B10:K10) -> 0
A11: NBIP_Dokudula | B11: 0 | C11: 0 | D11: 0 | E11: 0 | F11: 0 | G11: 0 | H11: 0 | I11: 0 | J11: 0 | K11: 0 | L11: =SUM(B11:K11) -> 0
A12: NBIP_Gesa | B12: 1969.85 | C12: 14.91 | D12: 7020.68 | E12: 74.17 | F12: 2.12 | G12: 5.4 | H12: 94.3 | I12: 1.4 | J12: 5.9 | K12: 12228.31 | L12: =SUM(B12:K12) -> 21417.04
A13: NBIP_Ghombua | B13: 2813.43 | C13: 9.51 | D13: 6170.76 | E13: 118.87 | F13: 11.95 | G13: 0.4 | H13: 36.3 | I13: 0.7 | J13: 3.2 | K13: 10729.8 | L13: =SUM(B13:K13) -> 19894.92
... A60: Total | B60: 39417.23 | C60: 496.95 | D60: 168310.16 | E60: 1666.35 | F60: 453.65 | G60: 142.1 | H60: 4469 | I60: 32.7 | J60: 78.2 | K60: 204673.94 | L60: =SUM(B60:K60) -> 419740.28

Sheet apr_25
A1: Location | B1: NBIP-NBIP Calls Revenue | C1: Fixed Calls Revenue | D1: Telekom Calls Revenue | E1: BMobile Calls Revenue | F1: Intl Calls Revenue | G1: A2P SMS Revenue | H1: Telekom SMS Revenue | I1: BMobile SMS Revenue | J1: Intl SMS Revenue | K1: Mobile Data Revenue | L1: Total
A2: NBIP_ANUHA | B2: 1725.41 | C2: 19.71 | D2: 5604.46 | E2: 52.01 | F2: 4.38 | G2: 1.2 | H2: 67.8 | I2: 0.1 | J2: 0.6 | K2: 4847.99 | L2: =SUM(B2:K2) -> 12323.66
A3: NBIP_Babasu | B3: 144.64 | C3: 5.98 | D3: 1239.96 | E3: 10.53 | F3: 5.28 | G3: 1.9 | H3: 11.6 | I3: 0 | J3: 0 | K3: 1121.55 | L3: =SUM(B3:K3) -> 2541.44
A4: NBIP_Bambakani | B4: 0 | C4: 0 | D4: 0 | E4: 0 | F4: 0 | G4: 0 | H4: 0 | I4: 0 | J4: 0 | K4: 0 | L4: =SUM(B4:K4) -> 0
A5: NBIP_Baniata | B5: 0 | C5: 0 | D5: 0 | E5: 0 | F5: 0 | G5: 0 | H5: 0 | I5: 0 | J5: 0 | K5: 0 | L5: =SUM(B5:K5) -> 0
A6: NBIP_BELAGA | B6: 1470.12 | C6: 23.55 | D6: 8208.29 | E6: 152.67 | F6: 5.05 | G6: 1.1 | H6: 110.4 | I6: 0.9 | J6: 1.5 | K6: 4308.79 | L6: =SUM(B6:K6) -> 14282.37
A7: NBIP_BITILA/KUSINI | B7: 191.04 | C7: 17.49 | D7: 2375.32 | E7: 45.95 | F7: 173.87 | G7: 0.9 | H7: 57.2 | I7: 0.5 | J7: 2.2 | K7: 4463.97 | L7: =SUM(B7:K7) -> 7328.44
A8: NBIP_BOLITEI | B8: 738.84 | C8: 24.27 | D8: 7527.37 | E8: 12.96 | F8: 1.23 | G8: 1 | H8: 131.9 | I8: 0.6 | J8: 3.5 | K8: 7461.41 | L8: =SUM(B8:K8) -> 15903.08
A9: NBIP_Bubunughu | B9: 3018.42 | C9: 16.09 | D9: 5910.8 | E9: 59.69 | F9: 2.02 | G9: 1.3 | H9: 58 | I9: 0.3 | J9: 1.7 | K9: 9015.67 | L9: =SUM(B9:K9) -> 18083.99
A10: NBIP_CHIVOKA | B10: 0 | C10: 0 | D10: 0 | E10: 0 | F10: 0 | G10: 0 | H10: 0 | I10: 0 | J10: 0 | K10: 0 | L10: =SUM(B10:K10) -> 0
A11: NBIP_Dokudula | B11: 0 | C11: 0 | D11: 0 | E11: 0 | F11: 0 | G11: 0 | H11: 0 | I11: 0 | J11: 0 | K11: 0 | L11: =SUM(B11:K11) -> 0
A12: NBIP_Gesa | B12: 2281.97 | C12: 20.76 | D12: 6715.28 | E12: 58.97 | F12: 1.12 | G12: 3 | H12: 125.3 | I12: 2.8 | J12: 3.4 | K12: 17795.2 | L12: =SUM(B12:K12) -> 27007.8
A13: NBIP_Ghombua | B13: 3664.05 | C13: 9.95 | D13: 6877.04 | E13: 46.56 | F13: 8.25 | G13: 0.9 | H13: 55.4 | I13: 0.4 | J13: 8.9 | K13: 18490.89 | L13: =SUM(B13:K13) -> 29162.34
... A60: Total | B60: 40007.38 | C60: 526.57 | D60: 158909.39 | E60: 1245.22 | F60: 463.92 | G60: 106.4 | H60: 3785.2 | I60: 18.5 | J60: 82.1 | K60: 265341.11 | L60: =SUM(B60:K60) -> 470485.79

Sheet may_25
A1: Location | B1: NBIP-NBIP Calls Revenue | C1: Fixed Calls Revenue | D1: Telekom Calls Revenue | E1: BMobile Calls Revenue | F1: Intl Calls Revenue | G1: A2P SMS Revenue | H1: Telekom SMS Revenue | I1: BMobile SMS Revenue | J1: Intl SMS Revenue | K1: Mobile Data Revenue | L1: Total
A2: NBIP_ANUHA | B2: 2733.27 | C2: 17.62 | D2: 7252.76 | E2: 33.63 | F2: 11.71 | G2: 0.9 | H2: 108.6 | I2: 0.4 | J2: 3.3 | K2: 7073.51 | L2: =SUM(B2:K2) -> 17235.7
A3: NBIP_Babasu | B3: 228.65 | C3: 3.95 | D3: 1740.83 | E3: 2.82 | F3: 0.13 | G3: 1.9 | H3: 17.9 | I3: 0 | J3: 1.6 | K3: 1961.92 | L3: =SUM(B3:K3) -> 3959.7
A4: NBIP_Bambakani | B4: 0 | C4: 0 | D4: 0 | E4: 0 | F4: 0 | G4: 0 | H4: 0 | I4: 0 | J4: 0 | K4: 0 | L4: =SUM(B4:K4) -> 0
A5: NBIP_Baniata | B5: 0 | C5: 0 | D5: 0 | E5: 0 | F5: 0 | G5: 0 | H5: 0 | I5: 0 | J5: 0 | K5: 0 | L5: =SUM(B5:K5) -> 0
A6: NBIP_BELAGA | B6: 2910.7 | C6: 18.32 | D6: 8292.29 | E6: 111.32 | F6: 1 | G6: 2 | H6: 248.7 | I6: 1.2 | J6: 5.9 | K6: 6141.87 | L6: =SUM(B6:K6) -> 17733.3
A7: NBIP_BITILA/KUSINI | B7: 202.14 | C7: 6.15 | D7: 3026.23 | E7: 70.04 | F7: 93.45 | G7: 1.1 | H7: 52.2 | I7: 0.8 | J7: 16.5 | K7: 4376.12 | L7: =SUM(B7:K7) -> 7844.73
A8: NBIP_BOLITEI | B8: 992.25 | C8: 16.5 | D8: 7945 | E8: 6.61 | F8: 1.39 | G8: 0.5 | H8: 82.7 | I8: 0.1 | J8: 0 | K8: 4223.31 | L8: =SUM(B8:K8) -> 13268.36
A9: NBIP_Bubunughu | B9: 4044.37 | C9: 17.07 | D9: 6701.06 | E9: 142.12 | F9: 7.79 | G9: 3.4 | H9: 91.7 | I9: 3.4 | J9: 6.1 | K9: 11282.7 | L9: =SUM(B9:K9) -> 22299.71
A10: NBIP_CHIVOKA | B10: 0 | C10: 0 | D10: 0 | E10: 0 | F10: 0 | G10: 0 | H10: 0 | I10: 0 | J10: 0 | K10: 0 | L10: =SUM(B10:K10) -> 0
A11: NBIP_Dokudula | B11: 0 | C11: 0 | D11: 0 | E11: 0 | F11: 0 | G11: 0 | H11: 0 | I11: 0 | J11: 0 | K11: 0 | L11: =SUM(B11:K11) -> 0
A12: NBIP_Gesa | B12: 2667.78 | C12: 35.4 | D12: 7574.99 | E12: 43.29 | F12: 2.29 | G12: 11.3 | H12: 93.1 | I12: 0.3 | J12: 6.9 | K12: 18934.03 | L12: =SUM(B12:K12) -> 29369.38
A13: NBIP_Ghombua | B13: 3400.44 | C13: 13 | D13: 7727.1 | E13: 18.98 | F13: 6.1 | G13: 1 | H13: 88.5 | I13: 1.1 | J13: 5.1 | K13: 18526.08 | L13: =SUM(B13:K13) -> 29787.4
... A60: Total | B60: 48572.3 | C60: 586.35 | D60: 181507.26 | E60: 984.9 | F60: 227.68 | G60: 109 | H60: 4806.3 | I60: 14.8 | J60: 130.3 | K60: 311377.66 | L60: =SUM(B60:K60) -> 548316.55

Sheet jun_25
A1: Location | B1: NBIP-NBIP Calls Revenue | C1: Fixed Calls Revenue | D1: Telekom Calls Revenue | E1: BMobile Calls Revenue | F1: Intl Calls Revenue | G1: A2P SMS Revenue | H1: Telekom SMS Revenue | I1: BMobile SMS Revenue | J1: Intl SMS Revenue | K1: Mobile Data Revenue | L1: Total
A2: NBIP_ANUHA | B2: 3439.79 | C2: 19.75 | D2: 6824.18 | E2: 25 | F2: 4.12 | G2: 0.9 | H2: 88.8 | I2: 0.3 | J2: 2.5 | K2: 5687.34 | L2: =SUM(B2:K2) -> 16092.68
A3: NBIP_Babasu | B3: 177.5 | C3: 2.42 | D3: 1574.37 | E3: 2.69 | F3: 3.88 | G3: 0.7 | H3: 15.9 | I3: 0 | J3: 1.4 | K3: 2326.7 | L3: =SUM(B3:K3) -> 4105.56
A4: NBIP_Bambakani | B4: 0 | C4: 0 | D4: 0 | E4: 0 | F4: 0 | G4: 0 | H4: 0 | I4: 0 | J4: 0 | K4: 0 | L4: =SUM(B4:K4) -> 0
A5: NBIP_Baniata | B5: 0 | C5: 0 | D5: 0 | E5: 0 | F5: 0 | G5: 0 | H5: 0 | I5: 0 | J5: 0 | K5: 0 | L5: =SUM(B5:K5) -> 0
A6: NBIP_BELAGA | B6: 2420.79 | C6: 28.42 | D6: 8144.69 | E6: 71.68 | F6: 1.62 | G6: 1.6 | H6: 100.6 | I6: 0.8 | J6: 3.2 | K6: 6642.53 | L6: =SUM(B6:K6) -> 17415.93
A7: NBIP_BITILA/KUSINI | B7: 299.87 | C7: 6.26 | D7: 3459.97 | E7: 22.22 | F7: 1.3 | G7: 0.1 | H7: 50.1 | I7: 0.1 | J7: 6.1 | K7: 4276.57 | L7: =SUM(B7:K7) -> 8122.59
A8: NBIP_BOLITEI | B8: 749.05 | C8: 33.33 | D8: 8341.78 | E8: 9.58 | F8: 1.58 | G8: 0.4 | H8: 290.9 | I8: 0 | J8: 1.9 | K8: 6538.73 | L8: =SUM(B8:K8) -> 15967.25
A9: NBIP_Bubunughu | B9: 3448.74 | C9: 18.49 | D9: 6734.38 | E9: 10.79 | F9: 0.78 | G9: 1.7 | H9: 67.5 | I9: 0.3 | J9: 1.6 | K9: 7972.79 | L9: =SUM(B9:K9) -> 18257.07
A10: NBIP_CHIVOKA | B10: 0 | C10: 0 | D10: 0 | E10: 0 | F10: 0 | G10: 0 | H10: 0 | I10: 0 | J10: 0 | K10: 0 | L10: =SUM(B10:K10) -> 0
A11: NBIP_Dokudula | B11: 0 | C11: 0 | D11: 0 | E11: 0 | F11: 0 | G11: 0 | H11: 0 | I11: 0 | J11: 0 | K11: 0 | L11: =SUM(B11:K11) -> 0
A12: NBIP_Gesa | B12: 2831.1 | C12: 28.12 | D12: 8824.44 | E12: 26.14 | F12: 2.26 | G12: 2 | H12: 168.2 | I12: 0.6 | J12: 7.2 | K12: 16539.74 | L12: =SUM(B12:K12) -> 28429.8
A13: NBIP_Ghombua | B13: 4296.92 | C13: 10.36 | D13: 8219.05 | E13: 25.71 | F13: 3.27 | G13: 2.9 | H13: 78.5 | I13: 1.5 | J13: 9.4 | K13: 21874.23 | L13: =SUM(B13:K13) -> 34521.84
... A60: Total | B60: 52938.65 | C60: 674.18 | D60: 201270.43 | E60: 557.11 | F60: 156.11 | G60: 70.7 | H60: 5159.1 | I60: 11 | J60: 112.6 | K60: 309842.37 | L60: =SUM(B60:K60) -> 570792.25

Sheet jul_25
A1: Location | B1: NBIP-NBIP Calls Revenue | C1: Fixed Calls Revenue | D1: Telekom Calls Revenue | E1: BMobile Calls Revenue | F1: Intl Calls Revenue | G1: A2P SMS Revenue | H1: Telekom SMS Revenue | I1: BMobile SMS Revenue | J1: Intl SMS Revenue | K1: Mobile Data Revenue | L1: Total
A2: NBIP_ANUHA | B2: 1574.71 | C2: 20.33 | D2: 4119.9 | E2: 21.98 | F2: 0.64 | G2: 0.8 | H2: 36.8 | I2: 0 | J2: 5.2 | K2: 4852.14 | L2: =SUM(B2:K2) -> 10632.5
A3: NBIP_Babasu | B3: 277.78 | C3: 4.55 | D3: 1892.83 | E3: 0.42 | F3: 0.03 | G3: 0.6 | H3: 31.4 | I3: 0.1 | J3: 2.1 | K3: 3649.84 | L3: =SUM(B3:K3) -> 5859.65
A4: NBIP_Bambakani | B4: 0 | C4: 0 | D4: 0 | E4: 0 | F4: 0 | G4: 0 | H4: 0 | I4: 0 | J4: 0 | K4: 0 | L4: =SUM(B4:K4) -> 0
A5: NBIP_Baniata | B5: 0 | C5: 0 | D5: 0 | E5: 0 | F5: 0 | G5: 0 | H5: 0 | I5: 0 | J5: 0 | K5: 0 | L5: =SUM(B5:K5) -> 0
A6: NBIP_BELAGA | B6: 1890.13 | C6: 29.7 | D6: 8748.52 | E6: 85.41 | F6: 4.8 | G6: 1.5 | H6: 86.2 | I6: 0.4 | J6: 1.9 | K6: 8795.63 | L6: =SUM(B6:K6) -> 19644.19
A7: NBIP_BITILA/KUSINI | B7: 230.19 | C7: 3.74 | D7: 3638.79 | E7: 9.58 | F7: 2.38 | G7: 1.1 | H7: 54.6 | I7: 0 | J7: 5 | K7: 5997.55 | L7: =SUM(B7:K7) -> 9942.93
A8: NBIP_BOLITEI | B8: 711.69 | C8: 50.19 | D8: 7819.86 | E8: 32.76 | F8: 2.86 | G8: 1 | H8: 159.4 | I8: 0.2 | J8: 1.6 | K8: 6174.15 | L8: =SUM(B8:K8) -> 14953.71
A9: NBIP_Bubunughu | B9: 2978.33 | C9: 9.76 | D9: 7524.87 | E9: 9.7 | F9: 0.83 | G9: 5.2 | H9: 114.6 | I9: 0.3 | J9: 3 | K9: 9874.13 | L9: =SUM(B9:K9) -> 20520.72
A10: NBIP_CHIVOKA | B10: 0 | C10: 0 | D10: 0 | E10: 0 | F10: 0 | G10: 0 | H10: 0 | I10: 0 | J10: 0 | K10: 0 | L10: =SUM(B10:K10) -> 0
A11: NBIP_Dokudula | B11: 0 | C11: 0 | D11: 0 | E11: 0 | F11: 0 | G11: 0 | H11: 0 | I11: 0 | J11: 0 | K11: 0 | L11: =SUM(B11:K11) -> 0
A12: NBIP_Gesa | B12: 3048.8 | C12: 20.35 | D12: 8757.83 | E12: 15.45 | F12: 0.74 | G12: 3 | H12: 183.4 | I12: 0.1 | J12: 1.7 | K12: 20335.21 | L12: =SUM(B12:K12) -> 32366.58
A13: NBIP_Ghombua | B13: 4318.94 | C13: 20.42 | D13: 9126.78 | E13: 26.7 | F13: 1.3 | G13: 10.5 | H13: 162.9 | I13: 0.8 | J13: 5.2 | K13: 28192.08 | L13: =SUM(B13:K13) -> 41865.62
... A60: Total | B60: 44938.65 | C60: 831.93 | D60: 228262.78 | E60: 542.93 | F60: 135.05 | G60: 85.9 | H60: 8128.7 | I60: 8.4 | J60: 141.1 | K60: 428680.59 | L60: =SUM(B60:K60) -> 711756.03

Sheet aug_25
A1: Location | B1: NBIP-NBIP Calls Revenue | C1: Fixed Calls Revenue | D1: Telekom Calls Revenue | E1: BMobile Calls Revenue | F1: Intl Calls Revenue | G1: A2P SMS Revenue | H1: Telekom SMS Revenue | I1: BMobile SMS Revenue | J1: Intl SMS Revenue | K1: Mobile Data Revenue | L1: Total
A2: NBIP_ANUHA | B2: 2240.57 | C2: 41.24 | D2: 7486.45 | E2: 32.58 | F2: 0.49 | G2: 1.1 | H2: 71.6 | I2: 0.1 | J2: 5.5 | K2: 8141.08 | L2: =SUM(B2:K2) -> 18020.71
A3: NBIP_Babasu | B3: 236.42 | C3: 1.8 | D3: 1131.26 | E3: 0.99 | F3: 0.09 | G3: 0.5 | H3: 20.4 | I3: 0 | J3: 0.3 | K3: 3335.41 | L3: =SUM(B3:K3) -> 4727.17
A4: NBIP_Bambakani | B4: 0 | C4: 0 | D4: 0 | E4: 0 | F4: 0 | G4: 0 | H4: 0 | I4: 0 | J4: 0 | K4: 0 | L4: =SUM(B4:K4) -> 0
A5: NBIP_Baniata | B5: 0 | C5: 0 | D5: 0 | E5: 0 | F5: 0 | G5: 0 | H5: 0 | I5: 0 | J5: 0 | K5: 0 | L5: =SUM(B5:K5) -> 0
A6: NBIP_BELAGA | B6: 2769.63 | C6: 16.33 | D6: 8499.04 | E6: 68.46 | F6: 3.02 | G6: 1.8 | H6: 89 | I6: 0.2 | J6: 1.4 | K6: 9613.02 | L6: =SUM(B6:K6) -> 21061.9
A7: NBIP_BITILA/KUSINI | B7: 309.22 | C7: 8.2 | D7: 4647.54 | E7: 22.02 | F7: 0.31 | G7: 1 | H7: 90 | I7: 0 | J7: 3.2 | K7: 7588.77 | L7: =SUM(B7:K7) -> 12670.26
A8: NBIP_BOLITEI | B8: 1248.41 | C8: 22.78 | D8: 7794.33 | E8: 1.3 | F8: 0.3 | G8: 1.7 | H8: 155.5 | I8: 0 | J8: 2.1 | K8: 5908.27 | L8: =SUM(B8:K8) -> 15134.69
A9: NBIP_Bubunughu | B9: 5083.1 | C9: 12.67 | D9: 8076.34 | E9: 22.54 | F9: 1.51 | G9: 3.2 | H9: 148.4 | I9: 0 | J9: 2 | K9: 10160 | L9: =SUM(B9:K9) -> 23509.76
A10: NBIP_CHIVOKA | B10: 0 | C10: 0 | D10: 0 | E10: 0 | F10: 0 | G10: 0 | H10: 0 | I10: 0 | J10: 0 | K10: 0 | L10: =SUM(B10:K10) -> 0
A11: NBIP_Dokudula | B11: 0 | C11: 0 | D11: 0 | E11: 0 | F11: 0 | G11: 0 | H11: 0 | I11: 0 | J11: 0 | K11: 0 | L11: =SUM(B11:K11) -> 0
A12: NBIP_Gesa | B12: 3739.82 | C12: 44.17 | D12: 8476.72 | E12: 57.93 | F12: 1.16 | G12: 6.7 | H12: 174.1 | I12: 0.5 | J12: 8.5 | K12: 29516.21 | L12: =SUM(B12:K12) -> 42025.81
A13: NBIP_Ghombua | B13: 4208.15 | C13: 8.47 | D13: 8016.26 | E13: 20.82 | F13: 2.51 | G13: 7.4 | H13: 73.7 | I13: 0 | J13: 3 | K13: 27505.65 | L13: =SUM(B13:K13) -> 39845.96
... A60: Total | B60: 84057.52 | C60: 1049.87 | D60: 280529.32 | E60: 652.56 | F60: 110.04 | G60: 96.7 | H60: 7997 | I60: 4.3 | J60: 162.6 | K60: 544344.13 | L60: =SUM(B60:K60) -> 919004.04

Sheet sep_25
A1: Location | B1: NBIP-NBIP Calls Revenue | C1: Fixed Calls Revenue | D1: Telekom Calls Revenue | E1: BMobile Calls Revenue | F1: Intl Calls Revenue | G1: A2P SMS Revenue | H1: Telekom SMS Revenue | I1: BMobile SMS Revenue | J1: Intl SMS Revenue | K1: Mobile Data Revenue | L1: Total
A2: NBIP_ANUHA | B2: 1929.67 | C2: 22.18 | D2: 6595.35 | E2: 15.6 | F2: 0.96 | G2: 1.4 | H2: 52.7 | I2: 1.1 | J2: 4.7 | K2: 7309.43 | L2: =SUM(B2:K2) -> 15933.09
A3: NBIP_Babasu | B3: 158.35 | C3: 2.01 | D3: 1290.5 | E3: 8.91 | F3: 0.09 | G3: 0.1 | H3: 12.6 | I3: 0.1 | J3: 0 | K3: 1812.27 | L3: =SUM(B3:K3) -> 3284.93
A4: NBIP_Bambakani | B4: 0 | C4: 0 | D4: 0 | E4: 0 | F4: 0 | G4: 0 | H4: 0 | I4: 0 | J4: 0 | K4: 0 | L4: =SUM(B4:K4) -> 0
A5: NBIP_Baniata | B5: 0 | C5: 0.09 | D5: 156.51 | E5: 0 | F5: 0 | G5: 0 | H5: 0.7 | I5: 0 | J5: 0.1 | K5: 45.27 | L5: =SUM(B5:K5) -> 202.67
A6: NBIP_BELAGA | B6: 2530.88 | C6: 23.67 | D6: 7800.51 | E6: 24.91 | F6: 0.32 | G6: 2.4 | H6: 110.8 | I6: 0 | J6: 3.3 | K6: 9733.31 | L6: =SUM(B6:K6) -> 20230.1
A7: NBIP_BITILA/KUSINI | B7: 491.55 | C7: 7.15 | D7: 5276.64 | E7: 3.42 | F7: 2.28 | G7: 0.9 | H7: 137.6 | I7: 0.1 | J7: 2.7 | K7: 8355.66 | L7: =SUM(B7:K7) -> 14278
A8: NBIP_BOLITEI | B8: 1135.89 | C8: 21.25 | D8: 7627.1 | E8: 10.78 | F8: 0.28 | G8: 1.1 | H8: 167.8 | I8: 0.1 | J8: 3.7 | K8: 6370.41 | L8: =SUM(B8:K8) -> 15338.41
A9: NBIP_Bubunughu | B9: 5321.35 | C9: 22.99 | D9: 8111.8 | E9: 8.58 | F9: 2.92 | G9: 2.9 | H9: 110 | I9: 0.3 | J9: 4.4 | K9: 10475.79 | L9: =SUM(B9:K9) -> 24061.03
A10: NBIP_CHIVOKA | B10: 0 | C10: 0 | D10: 0 | E10: 0 | F10: 0 | G10: 0 | H10: 0 | I10: 0 | J10: 0 | K10: 0 | L10: =SUM(B10:K10) -> 0
A11: NBIP_Dokudula | B11: 0 | C11: 0 | D11: 0 | E11: 0 | F11: 0 | G11: 0 | H11: 0 | I11: 0 | J11: 0 | K11: 0 | L11: =SUM(B11:K11) -> 0
A12: NBIP_Gesa | B12: 3419.65 | C12: 34.15 | D12: 7653.16 | E12: 30.96 | F12: 0.64 | G12: 8.4 | H12: 118.2 | I12: 0.3 | J12: 6.6 | K12: 24187.54 | L12: =SUM(B12:K12) -> 35459.6
A13: NBIP_Ghombua | B13: 4949.59 | C13: 12.47 | D13: 9094.24 | E13: 42.27 | F13: 2.84 | G13: 6.1 | H13: 72.5 | I13: 0.3 | J13: 9.1 | K13: 26068.8 | L13: =SUM(B13:K13) -> 40258.21
... A60: Total | B60: 102001.52 | C60: 1228.77 | D60: 306352.95 | E60: 529.96 | F60: 81.29 | G60: 100.2 | H60: 8423.8 | I60: 6.3 | J60: 159.6 | K60: 597150.69 | L60: =SUM(B60:K60) -> 1016035.1

Sheet oct_25
A1: Location | B1: NBIP-NBIP Calls Revenue | C1: Fixed Calls Revenue | D1: Telekom Calls Revenue | E1: BMobile Calls Revenue | F1: Intl Calls Revenue | G1: A2P SMS Revenue | H1: Telekom SMS Revenue | I1: BMobile SMS Revenue | J1: Intl SMS Revenue | K1: Mobile Data Revenue | L1: Total
A2: NBIP_ANUHA | B2: 2456.32 | C2: 25.35 | D2: 7185.97 | E2: 89.95 | F2: 0.22 | G2: 2.6 | H2: 80.6 | I2: 3.5 | J2: 8.6 | K2: 15447.02 | L2: =SUM(B2:K2) -> 25300.13
A3: NBIP_Babasu | B3: 244.28 | C3: 3.08 | D3: 1344.75 | E3: 0 | F3: 0.21 | G3: 0.2 | H3: 13.4 | I3: 0 | J3: 0.7 | K3: 3252.53 | L3: =SUM(B3:K3) -> 4859.15
A4: NBIP_Bambakani | B4: 0 | C4: 9.6 | D4: 1326.41 | E4: 3.46 | F4: 0 | G4: 0.3 | H4: 16 | I4: 0 | J4: 0.1 | K4: 2183.93 | L4: =SUM(B4:K4) -> 3539.8
A5: NBIP_Baniata | B5: 761.68 | C5: 13.66 | D5: 2322.8 | E5: 0.94 | F5: 5.39 | G5: 1.7 | H5: 85.4 | I5: 0 | J5: 3.4 | K5: 5590.21 | L5: =SUM(B5:K5) -> 8785.18
A6: NBIP_BELAGA | B6: 2794.72 | C6: 38.49 | D6: 7375.99 | E6: 35.88 | F6: 0.27 | G6: 7.6 | H6: 89.8 | I6: 0.2 | J6: 2.2 | K6: 17585.74 | L6: =SUM(B6:K6) -> 27930.89
A7: NBIP_BITILA/KUSINI | B7: 1066.13 | C7: 32.72 | D7: 7084.62 | E7: 43.06 | F7: 0.05 | G7: 4.4 | H7: 159.2 | I7: 0.2 | J7: 5.2 | K7: 10920.48 | L7: =SUM(B7:K7) -> 19316.06
A8: NBIP_BOLITEI | B8: 1644.36 | C8: 22.73 | D8: 8862.77 | E8: 20.24 | F8: 0.5 | G8: 2.5 | H8: 134.5 | I8: 0.1 | J8: 1.8 | K8: 10140.56 | L8: =SUM(B8:K8) -> 20830.06
A9: NBIP_Bubunughu | B9: 5087.59 | C9: 21.79 | D9: 7651.29 | E9: 27.53 | F9: 0.63 | G9: 3.1 | H9: 148.6 | I9: 0.1 | J9: 3.6 | K9: 10772.67 | L9: =SUM(B9:K9) -> 23716.9
A10: NBIP_CHIVOKA | B10: 0 | C10: 0 | D10: 0 | E10: 0 | F10: 0 | G10: 0 | H10: 0 | I10: 0 | J10: 0 | K10: 0 | L10: =SUM(B10:K10) -> 0
A11: NBIP_Dokudula | B11: 0 | C11: 1.07 | D11: 1972.62 | E11: 45.7 | F11: 0.37 | G11: 0 | H11: 242.6 | I11: 0 | J11: 0.9 | K11: 1897.69 | L11: =SUM(B11:K11) -> 4160.95
A12: NBIP_Gesa | B12: 3180.23 | C12: 31.77 | D12: 8913.44 | E12: 19.75 | F12: 6.82 | G12: 16.5 | H12: 110.8 | I12: 0 | J12: 6.3 | K12: 30031.87 | L12: =SUM(B12:K12) -> 42317.48
A13: NBIP_Ghombua | B13: 4392.01 | C13: 13.75 | D13: 8437.07 | E13: 38.53 | F13: 1.15 | G13: 9.1 | H13: 77.8 | I13: 0 | J13: 19.1 | K13: 23334.35 | L13: =SUM(B13:K13) -> 36322.86
... A60: Total | B60: 119994.74 | C60: 1470.07 | D60: 355332.85 | E60: 1036.98 | F60: 93.73 | G60: 313.4 | H60: 11278.4 | I60: 11.4 | J60: 227.1 | K60: 815680.14 | L60: =SUM(B60:K60) -> 1305438.8

Sheet nov_25
A1: Location | B1: NBIP-NBIP Calls Revenue | C1: Fixed Calls Revenue | D1: Telekom Calls Revenue | E1: BMobile Calls Revenue | F1: Intl Calls Revenue | G1: A2P SMS Revenue | H1: Telekom SMS Revenue | I1: BMobile SMS Revenue | J1: Intl SMS Revenue | K1: Mobile Data Revenue | L1: Total
A2: NBIP_ANUHA | B2: 2571.42 | C2: 31.82 | D2: 8184.59 | E2: 158.31 | F2: 0.29 | G2: 2.8 | H2: 74.6 | I2: 1.1 | J2: 4 | K2: 15333.88 | L2: =SUM(B2:K2) -> 26362.81
A3: NBIP_Babasu | B3: 293.1 | C3: 10.72 | D3: 1681.18 | E3: 0.62 | F3: 0.78 | G3: 0.5 | H3: 26.7 | I3: 0 | J3: 0.4 | K3: 5954.52 | L3: =SUM(B3:K3) -> 7968.52
A4: NBIP_Bambakani | B4: 675.1 | C4: 16.09 | D4: 3813.07 | E4: 9.72 | F4: 0.07 | G4: 1.4 | H4: 70.7 | I4: 0.1 | J4: 2.7 | K4: 8789.48 | L4: =SUM(B4:K4) -> 13378.43
A5: NBIP_Baniata | B5: 1102.27 | C5: 18.61 | D5: 2246.08 | E5: 0.45 | F5: 0.04 | G5: 0.5 | H5: 87.1 | I5: 0 | J5: 0.8 | K5: 8286.89 | L5: =SUM(B5:K5) -> 11742.74
A6: NBIP_BELAGA | B6: 2505.8 | C6: 20.03 | D6: 6519.95 | E6: 20.73 | F6: 0.39 | G6: 3.6 | H6: 81.6 | I6: 0.6 | J6: 3.4 | K6: 17424.18 | L6: =SUM(B6:K6) -> 26580.28
A7: NBIP_BITILA/KUSINI | B7: 1167.22 | C7: 18.43 | D7: 5912.32 | E7: 12.75 | F7: 0.1 | G7: 1.1 | H7: 157.2 | I7: 0 | J7: 12.4 | K7: 13702.96 | L7: =SUM(B7:K7) -> 20984.48
A8: NBIP_BOLITEI | B8: 2071.37 | C8: 15.44 | D8: 8327.34 | E8: 10.15 | F8: 1.12 | G8: 3.2 | H8: 143.6 | I8: 0 | J8: 2 | K8: 9544.66 | L8: =SUM(B8:K8) -> 20118.88
A9: NBIP_Bubunughu | B9: 4121.18 | C9: 26.69 | D9: 7357.51 | E9: 13.25 | F9: 0.32 | G9: 3 | H9: 174 | I9: 0.1 | J9: 3.8 | K9: 12663.27 | L9: =SUM(B9:K9) -> 24363.12
A10: NBIP_CHIVOKA | B10: 0 | C10: 0 | D10: 0 | E10: 0 | F10: 0 | G10: 0 | H10: 0 | I10: 0 | J10: 0 | K10: 0 | L10: =SUM(B10:K10) -> 0
A11: NBIP_Dokudula | B11: 1045.14 | C11: 4.3 | D11: 5145.32 | E11: 187 | F11: 0 | G11: 0.4 | H11: 241 | I11: 0 | J11: 1.6 | K11: 8394.31 | L11: =SUM(B11:K11) -> 15019.07
A12: NBIP_Gesa | B12: 2766.71 | C12: 24.57 | D12: 7616.46 | E12: 13.29 | F12: 2.93 | G12: 5.6 | H12: 167.1 | I12: 0.1 | J12: 7.2 | K12: 27016.17 | L12: =SUM(B12:K12) -> 37620.13
A13: NBIP_Ghombua | B13: 4088.22 | C13: 9.04 | D13: 8468.95 | E13: 20.48 | F13: 0.85 | G13: 5.2 | H13: 90.8 | I13: 0.4 | J13: 3.3 | K13: 24749.66 | L13: =SUM(B13:K13) -> 37436.9
... A17: NBIP_Husuzo | B17: 620.61 | C17: 12.35 | D17: 2868.15 | E17: 2.12 | F17: 0.37 | G17: 0.1 | H17: 98.1 | I17: 0 | J17: 2.2 | K17: 13839.62 | L17: =SUM(B17:K17) -> 17443.62
A18: NBIP_Jack Harbour | B18: 0 | C18: 0 | D18: 0 | E18: 0 | F18: 0 | G18: 0 | H18: 0 | I18: 0 | J18: 0 | K18: 0 | L18: 0
A19: NBIP_Jarihana | B19: 2409.87 | C19: 8.86 | D19: 5775.3 | E19: 31.69 | F19: 0.23 | G19: 1.7 | H19: 139.7 | I19: 0.3 | J19: 4.8 | K19: 17148.21 | L19: =SUM(B19:K19) -> 25520.66
A20: NBIP_Jejevo | B20: 1767.83 | C20: 31.12 | D20: 4690.88 | E20: 2.8 | F20: 0.7 | G20: 3 | H20: 140.1 | I20: 0 | J20: 4.7 | K20: 7295.73 | L20: =SUM(B20:K20) -> 13936.86
A21: NBIP_Jerico | B21: 0 | C21: 0 | D21: 0 | E21: 0 | F21: 0 | G21: 0 | H21: 0 | I21: 0 | J21: 0 | K21: 0 | L21: =SUM(B21:K21) -> 0
A22: NBIP_Kavolavata | B22: 1561.75 | C22: 28.69 | D22: 9061.2 | E22: 5.96 | F22: 2.18 | G22: 2.8 | H22: 264.2 | I22: 0 | J22: 3.7 | K22: 10196.52 | L22: =SUM(B22:K22) -> 21127
A23: NBIP_Kikinocho | B23: 2493.55 | C23: 7.16 | D23: 5731.48 | E23: 13.63 | F23: 1.78 | G23: 3.7 | H23: 50.6 | I23: 0.1 | J23: 3.1 | K23: 16309.57 | L23: =SUM(B23:K23) -> 24614.67
A24: NBIP_Koleasi | B24: 1242.17 | C24: 13.16 | D24: 2097.05 | E24: 3.28 | F24: 0 | G24: 4.4 | H24: 42.1 | I24: 0 | J24: 2 | K24: 9469.16 | L24: =SUM(B24:K24) -> 12873.32
A25: NBIP_Kolochulu | B25: 3076.55 | C25: 26.76 | D25: 8325.19 | E25: 26.27 | F25: 4.66 | G25: 7.7 | H25: 231 | I25: 0 | J25: 6.2 | K25: 23924.97 | L25: =SUM(B25:K25) -> 35629.3
A26: NBIP_Kolokofa | B26: 1221.67 | C26: 35.87 | D26: 5207.13 | E26: 0.4 | F26: 0.61 | G26: 4.1 | H26: 321.4 | I26: 0.3 | J26: 3.3 | K26: 5358.22 | L26: =SUM(B26:K26) -> 12153
A27: NBIP_Laugoata | B27: 1694.22 | C27: 9.97 | D27: 5739.03 | E27: 3.59 | F27: 1.3 | G27: 10.7 | H27: 51.9 | I27: 0 | J27: 5.5 | K27: 12497.69 | L27: =SUM(B27:K27) -> 20013.9
A28: NBIP_LELEA | B28: 1344.5 | C28: 32.45 | D28: 9379.89 | E28: 3.61 | F28: 0.14 | G28: 4.9 | H28: 121.1 | I28: 0.1 | J28: 2.2 | K28: 14287.25 | L28: =SUM(B28:K28) -> 25176.14
A29: NBIP_Leufoman | B29: 1303.58 | C29: 16.25 | D29: 4677.91 | E29: 1.68 | F29: 0.73 | G29: 2.5 | H29: 129.2 | I29: 0 | J29: 2.4 | K29: 19570.05 | L29: =SUM(B29:K29) -> 25704.3
A30: NBIP_Louna | B30: 2376.76 | C30: 14.96 | D30: 5130.2 | E30: 15.03 | F30: 3.31 | G30: 1.5 | H30: 74.2 | I30: 0 | J30: 3.8 | K30: 23462.96 | L30: =SUM(B30:K30) -> 31082.72
... A61: NBIP_Wanderer Bay | B61: 5369.33 | C61: 31.06 | D61: 8701.96 | E61: 7.66 | F61: 0.67 | G61: 5.3 | H61: 130.3 | I61: 0.1 | J61: 11.8 | K61: 16865.41 | L61: =SUM(B61:K61) -> 31123.59
A62: Total | B62: =SUM(B2:B61) -> 128803.14 | C62: =SUM(C2:C61) -> 1510.58 | D62: =SUM(D2:D61) -> 377364.61 | E62: =SUM(E2:E61) -> 1089.23 | F62: =SUM(F2:F61) -> 79.77 | G62: =SUM(G2:G61) -> 390.7 | H62: =SUM(H2:H61) -> 11738.4 | I62: =SUM(I2:I61) -> 7.2 | ... K62: =SUM(K2:K61) -> 905779.17 | L62: =SUM($L$2:L61) -> 1427004.6

Sheet dec_25
A1: Location | B1: NBIP-NBIP Calls Revenue | C1: Fixed Calls Revenue | D1: Telekom Calls Revenue | E1: BMobile Calls Revenue | F1: Intl Calls Revenue | G1: A2P SMS Revenue | H1: Telekom SMS Revenue | I1: BMobile SMS Revenue | J1: Intl SMS Revenue | K1: Mobile Data Revenue | L1: Total
A2: NBIP_ANUHA | B2: 3001.63 | C2: 21.32 | D2: 6706.64 | E2: 36.74 | F2: 0.9 | G2: 1 | H2: 117.1 | I2: 0 | J2: 1.9 | K2: 14291.58 | L2: =SUM(B2:K2) -> 24178.81
A3: NBIP_Babasu | B3: 533.11 | C3: 5.68 | D3: 2388.48 | E3: 0.15 | F3: 0.22 | G3: 0.3 | H3: 32.8 | I3: 0.1 | J3: 0.1 | K3: 7070.27 | L3: =SUM(B3:K3) -> 10031.21
A4: NBIP_Bambakani | B4: 629.26 | C4: 5.4 | D4: 3293.68 | E4: 3.35 | F4: 0.08 | G4: 0.7 | H4: 49.7 | I4: 0 | J4: 3.2 | K4: 9294.07 | L4: =SUM(B4:K4) -> 13279.44
A5: NBIP_Baniata | B5: 1511.07 | C5: 16.12 | D5: 3890.09 | E5: 0 | F5: 0.56 | G5: 0.8 | H5: 133.7 | I5: 0 | J5: 4 | K5: 8748.05 | L5: =SUM(B5:K5) -> 14304.39
A6: NBIP_BELAGA | B6: 2493.6 | C6: 23.68 | D6: 7489.37 | E6: 35.2 | F6: 0.48 | G6: 3.5 | H6: 121.9 | I6: 1 | J6: 3.1 | K6: 21394.74 | L6: =SUM(B6:K6) -> 31566.57
A7: NBIP_BITILA/KUSINI | B7: 893.46 | C7: 11.97 | D7: 4894.54 | E7: 30.1 | F7: 0.62 | G7: 2.4 | H7: 157.7 | I7: 0.3 | J7: 9.4 | K7: 14046.68 | L7: =SUM(B7:K7) -> 20047.17
A8: NBIP_BOLITEI | B8: 1505.55 | C8: 21.65 | D8: 8475.04 | E8: 7.11 | F8: 0.25 | G8: 4.8 | H8: 205.3 | I8: 0.1 | J8: 1.5 | K8: 11763.34 | L8: =SUM(B8:K8) -> 21984.64
A9: NBIP_Bubunughu | B9: 3672.43 | C9: 21.17 | D9: 6690.36 | E9: 12.9 | F9: 0.83 | G9: 26.7 | H9: 212.7 | I9: 0.8 | J9: 1.6 | K9: 15578.34 | L9: =SUM(B9:K9) -> 26217.83
A10: NBIP_CHIVOKO | B10: 317.2 | C10: 22.15 | D10: 3089.05 | E10: 1.78 | F10: 0.17 | G10: 0.4 | H10: 29.2 | I10: 0 | J10: 0.3 | K10: 4777.08 | L10: =SUM(B10:K10) -> 8237.33
A11: NBIP_Dokudula | B11: 826.85 | C11: 15.78 | D11: 4517.45 | E11: 43.71 | F11: 2.68 | G11: 0.6 | H11: 131.6 | I11: 0 | J11: 3.5 | K11: 9572.55 | L11: =SUM(B11:K11) -> 15114.72
A12: NBIP_Gesa | B12: 3129.16 | C12: 15.69 | D12: 7257.76 | E12: 19.88 | F12: 4.75 | G12: 10.4 | H12: 278.2 | I12: 0.3 | J12: 3.7 | K12: 20189.48 | L12: =SUM(B12:K12) -> 30909.32
A13: NBIP_Ghombua | B13: 4387.08 | C13: 10.49 | D13: 7394.15 | E13: 11.15 | F13: 2.48 | G13: 5.2 | H13: 117.1 | I13: 0.4 | J13: 2.3 | K13: 32635 | L13: =SUM(B13:K13) -> 44565.35
... A61: NBIP_Wanderer Bay | B61: 5210.51 | C61: 21.4 | D61: 7298.02 | E61: 22.25 | F61: 1.74 | G61: 3.3 | H61: 107.5 | I61: 0 | J61: 7.5 | K61: 18592.73 | L61: =SUM(B61:K61) -> 31264.95
A62: Total | B62: =SUM(B2:B61) -> 132402.63 | C62: =SUM(C2:C61) -> 1330.87 | D62: =SUM(D2:D61) -> 371793.98 | E62: =SUM(E2:E61) -> 916.15 | F62: =SUM(F2:F61) -> 96.69 | G62: =SUM(G2:G61) -> 268.9 | H62: =SUM(H2:H61) -> 14935.9 | I62: =SUM(I2:I61) -> 9.6 | ... K62: =SUM(K2:K61) -> 935441.22 | L62: =SUM($L$2:L61) -> 1457414.5

Sheet jan_26
A1: Location | B1: NBIP-NBIP Calls Revenue | C1: Fixed Calls Revenue | D1: Telekom Calls Revenue | E1: BMobile Calls Revenue | F1: Intl Calls Revenue | G1: A2P SMS Revenue | H1: Telekom SMS Revenue | I1: BMobile SMS Revenue | J1: Intl SMS Revenue | K1: Mobile Data Revenue | L1: Total
A2: NBIP_ANUHA | B2: 1788.1 | C2: 18.34 | D2: 4722.17 | E2: 17.12 | F2: 1.05 | G2: 0.9 | H2: 41.3 | I2: 0.1 | J2: 1.5 | K2: 11252.21 | L2: =SUM(B2:K2) -> 17842.79
A3: NBIP_Babasu | B3: 590.8 | C3: 11.61 | D3: 2725.8 | E3: 10.62 | F3: 0.02 | G3: 1 | H3: 40.8 | I3: 0.1 | J3: 0.2 | K3: 7097.55 | L3: =SUM(B3:K3) -> 10478.5
A4: NBIP_Bambakani | B4: 585.47 | C4: 13.8 | D4: 2014.89 | E4: 2.59 | F4: 0.14 | G4: 0.8 | H4: 48.8 | I4: 0 | J4: 2.9 | K4: 8262.59 | L4: =SUM(B4:K4) -> 10931.98
A5: NBIP_Baniata | B5: 903.26 | C5: 21.86 | D5: 2821.28 | E5: 0.29 | F5: 1.06 | G5: 0.3 | H5: 79.9 | I5: 0 | J5: 0.9 | K5: 7228.94 | L5: =SUM(B5:K5) -> 11057.79
A6: NBIP_BELAGA | B6: 2440.6 | C6: 34.67 | D6: 6799.97 | E6: 13.95 | F6: 1.22 | G6: 1.7 | H6: 70.4 | I6: 0.1 | J6: 0.6 | K6: 18846.47 | L6: =SUM(B6:K6) -> 28209.68
A7: NBIP_BITILA/KUSINI | B7: 1336.14 | C7: 10 | D7: 3972.72 | E7: 51.9 | F7: 0.6 | G7: 0.6 | H7: 156.6 | I7: 0.2 | J7: 3.4 | K7: 16458.58 | L7: =SUM(B7:K7) -> 21990.74
A8: NBIP_BOLITEI | B8: 1447.11 | C8: 16.38 | D8: 7161.24 | E8: 0 | F8: 8.6 | G8: 1.9 | H8: 219.4 | I8: 0 | J8: 1.6 | K8: 10754.98 | L8: =SUM(B8:K8) -> 19611.21
A9: NBIP_Bubunughu | B9: 3773.86 | C9: 37.61 | D9: 6190.81 | E9: 6.49 | F9: 0.82 | G9: 21.2 | H9: 168.4 | I9: 0.2 | J9: 1.7 | K9: 15197.55 | L9: =SUM(B9:K9) -> 25398.64
A10: NBIP_CHIVOKO | B10: 260.87 | C10: 29.9 | D10: 3111.97 | E10: 8.91 | F10: 0.17 | G10: 0.4 | H10: 82.4 | I10: 0 | J10: 0 | K10: 7427.33 | L10: =SUM(B10:K10) -> 10921.95
A11: NBIP_Dokudula | B11: 523.62 | C11: 21.65 | D11: 3152.44 | E11: 1.31 | F11: 1.45 | G11: 1 | H11: 242.3 | I11: 0 | J11: 2.5 | K11: 7950.96 | L11: =SUM(B11:K11) -> 11897.23
A12: NBIP_Gesa | B12: 2381.98 | C12: 20.51 | D12: 6250.67 | E12: 4.92 | F12: 0.39 | G12: 34.3 | H12: 281 | I12: 0.4 | J12: 11.5 | K12: 17234.1 | L12: =SUM(B12:K12) -> 26219.77
A13: NBIP_Ghombua | B13: 4266.02 | C13: 19.41 | D13: 7179.33 | E13: 6.49 | F13: 1.09 | G13: 5.2 | H13: 129 | I13: 0.8 | J13: 4.4 | K13: 32130.23 | L13: =SUM(B13:K13) -> 43741.97
... A62: NBIP_Wanderer Bay | B62: 4789.5 | C62: 28.4 | D62: 6050.14 | E62: 6.27 | F62: 1.57 | G62: 3.5 | H62: 130.8 | I62: 0 | J62: 1.8 | K62: 16711.31 | L62: =SUM(B62:K62) -> 27723.29
A63: Total | B63: =SUM(B2:B62) -> 113185.14 | C63: =SUM(C2:C62) -> 1458.01 | D63: =SUM(D2:D62) -> 308685.09 | E63: =SUM(E2:E62) -> 575.82 | F63: =SUM(F2:F62) -> 90.35 | G63: =SUM(G2:G62) -> 418.5 | H63: =SUM(H2:H62) -> 15678.2 | I63: =SUM(I2:I62) -> 6.8 | ... K63: =SUM(K2:K62) -> 909172.9 | L63: =SUM($L$2:L62) -> 1349389.7

Sheet Sheet22
A1: Location | B1: MAR | C1: APR | D1: MAY | E1: JUN | F1: JULY | G1: AUG | H1: SEP | I1: OCT | J1: NOV | K1: DEC | L1: JAN | M1: FEB | N1: MAR | O1: APR | P1: MAY | Q1: JUNE | R1: JULY | S1: AUGUST | T1: SEPTEMBER | U1: OCTOBER | V1: NOVEMBER | W1: DECEMBER | X1: JANUARY | Y1: FEBRUARY | Z1: MARCH
A2: NBIP_ANUHA | B2: =mar_24!L2 -> 0 | C2: =apr_24!L2 -> 0 | D2: =may_24!$L2 -> 0 | E2: =jun_24!$L2 -> 0 | F2: =jul_24!$L2 -> 0 | G2: =aug_24!$L2 -> 0 | H2: =sep_24!$L2 -> 0 | I2: =oct_24!$L2 -> 0 | J2: =nov_24!$L2 -> 0 | K2: =dec_24!$L2 -> 7700.94 | L2: =jan_25!$L2 -> 17159.4 | M2: =feb_25!$L2 -> 11634.59 | N2: =mar_25!$L2 -> 12540.3 | O2: =apr_25!$L2 -> 12323.66 | P2: =may_25!$L2 -> 17235.7 | Q2: =jun_25!$L2 -> 16092.68 | R2: =jul_25!$L2 -> 10632.5 | S2: =aug_25!$L2 -> 18020.71 | T2: =sep_25!$L2 -> 15933.09 | U2: =oct_25!$L2 -> 25300.13 | V2: =nov_25!$L2 -> 26362.81 | W2: =dec_25!L2 -> 24178.81 | X2: =jan_26!L2 -> 17842.79
A3: NBIP_Babasu | B3: =mar_24!L3 -> 0 | C3: =apr_24!L3 -> 0 | D3: =may_24!$L3 -> 0 | E3: =jun_24!$L3 -> 0 | F3: =jul_24!$L3 -> 0 | G3: =aug_24!$L3 -> 0 | H3: =sep_24!$L3 -> 382.47 | I3: =oct_24!$L3 -> 4011.36 | J3: =nov_24!$L3 -> 3232.69 | K3: =dec_24!$L3 -> 4237.17 | L3: =jan_25!$L3 -> 4949.95 | M3: =feb_25!$L3 -> 2844.17 | N3: =mar_25!$L3 -> 2425.38 | O3: =apr_25!$L3 -> 2541.44 | P3: =may_25!$L3 -> 3959.7 | Q3: =jun_25!$L3 -> 4105.56 | R3: =jul_25!$L3 -> 5859.65 | S3: =aug_25!$L3 -> 4727.17 | T3: =sep_25!$L3 -> 3284.93 | U3: =oct_25!$L3 -> 4859.15 | V3: =nov_25!$L3 -> 7968.52 | W3: =dec_25!L3 -> 10031.21 | X3: =jan_26!L3 -> 10478.5
A4: NBIP_Bambakani | B4: =mar_24!L4 -> 0 | C4: =apr_24!L4 -> 0 | D4: =may_24!$L4 -> 0 | E4: =jun_24!$L4 -> 0 | F4: =jul_24!$L4 -> 0 | G4: =aug_24!$L4 -> 0 | H4: =sep_24!$L4 -> 0 | I4: =oct_24!$L4 -> 0 | J4: =nov_24!$L4 -> 0 | K4: =dec_24!$L4 -> 0 | L4: =jan_25!$L4 -> 0 | M4: =feb_25!$L4 -> 0 | N4: =mar_25!$L4 -> 0 | O4: =apr_25!$L4 -> 0 | P4: =may_25!$L4 -> 0 | Q4: =jun_25!$L4 -> 0 | R4: =jul_25!$L4 -> 0 | S4: =aug_25!$L4 -> 0 | T4: =sep_25!$L4 -> 0 | U4: =oct_25!$L4 -> 3539.8 | V4: =nov_25!$L4 -> 13378.43 | W4: =dec_25!L4 -> 13279.44 | X4: =jan_26!L4 -> 10931.98
A5: NBIP_Baniata | B5: =mar_24!L5 -> 0 | C5: =apr_24!L5 -> 0 | D5: =may_24!$L5 -> 0 | E5: =jun_24!$L5 -> 0 | F5: =jul_24!$L5 -> 0 | G5: =aug_24!$L5 -> 0 | H5: =sep_24!$L5 -> 0 | I5: =oct_24!$L5 -> 0 | J5: =nov_24!$L5 -> 0 | K5: =dec_24!$L5 -> 0 | L5: =jan_25!$L5 -> 0 | M5: =feb_25!$L5 -> 0 | N5: =mar_25!$L5 -> 0 | O5: =apr_25!$L5 -> 0 | P5: =may_25!$L5 -> 0 | Q5: =jun_25!$L5 -> 0 | R5: =jul_25!$L5 -> 0 | S5: =aug_25!$L5 -> 0 | T5: =sep_25!$L5 -> 202.67 | U5: =oct_25!$L5 -> 8785.18 | V5: =nov_25!$L5 -> 11742.74 | W5: =dec_25!L5 -> 14304.39 | X5: =jan_26!L5 -> 11057.79
A6: NBIP_BELAGA | B6: =mar_24!L6 -> 0 | C6: =apr_24!L6 -> 0 | D6: =may_24!$L6 -> 0 | E6: =jun_24!$L6 -> 0 | F6: =jul_24!$L6 -> 0 | G6: =aug_24!$L6 -> 0 | H6: =sep_24!$L6 -> 0 | I6: =oct_24!$L6 -> 0 | J6: =nov_24!$L6 -> 0 | K6: =dec_24!$L6 -> 7134.51 | L6: =jan_25!$L6 -> 20769.73 | M6: =feb_25!$L6 -> 12040.1 | N6: =mar_25!$L6 -> 13277.9 | O6: =apr_25!$L6 -> 14282.37 | P6: =may_25!$L6 -> 17733.3 | Q6: =jun_25!$L6 -> 17415.93 | R6: =jul_25!$L6 -> 19644.19 | S6: =aug_25!$L6 -> 21061.9 | T6: =sep_25!$L6 -> 20230.1 | U6: =oct_25!$L6 -> 27930.89 | V6: =nov_25!$L6 -> 26580.28 | W6: =dec_25!L6 -> 31566.57 | X6: =jan_26!L6 -> 28209.68
A7: NBIP_BITILA/KUSINI | B7: =mar_24!L7 -> 0 | C7: =apr_24!L7 -> 0 | D7: =may_24!$L7 -> 0 | E7: =jun_24!$L7 -> 0 | F7: =jul_24!$L7 -> 0 | G7: =aug_24!$L7 -> 0 | H7: =sep_24!$L7 -> 0 | I7: =oct_24!$L7 -> 0 | J7: =nov_24!$L7 -> 0 | K7: =dec_24!$L7 -> 3712.05 | L7: =jan_25!$L7 -> 8250.63 | M7: =feb_25!$L7 -> 7575.11 | N7: =mar_25!$L7 -> 9013.74 | O7: =apr_25!$L7 -> 7328.44 | P7: =may_25!$L7 -> 7844.73 | Q7: =jun_25!$L7 -> 8122.59 | R7: =jul_25!$L7 -> 9942.93 | S7: =aug_25!$L7 -> 12670.26 | T7: =sep_25!$L7 -> 14278 | U7: =oct_25!$L7 -> 19316.06 | V7: =nov_25!$L7 -> 20984.48 | W7: =dec_25!L7 -> 20047.17 | X7: =jan_26!L7 -> 21990.74
A8: NBIP_BOLITEI | B8: =mar_24!L8 -> 0 | C8: =apr_24!L8 -> 0 | D8: =may_24!$L8 -> 0 | E8: =jun_24!$L8 -> 0 | F8: =jul_24!$L8 -> 0 | G8: =aug_24!$L8 -> 0 | H8: =sep_24!$L8 -> 0 | I8: =oct_24!$L8 -> 0 | J8: =nov_24!$L8 -> 0 | K8: =dec_24!$L8 -> 6174.17 | L8: =jan_25!$L8 -> 18401.31 | M8: =feb_25!$L8 -> 13610.06 | N8: =mar_25!$L8 -> 16960.25 | O8: =apr_25!$L8 -> 15903.08 | P8: =may_25!$L8 -> 13268.36 | Q8: =jun_25!$L8 -> 15967.25 | R8: =jul_25!$L8 -> 14953.71 | S8: =aug_25!$L8 -> 15134.69 | T8: =sep_25!$L8 -> 15338.41 | U8: =oct_25!$L8 -> 20830.06 | V8: =nov_25!$L8 -> 20118.88 | W8: =dec_25!L8 -> 21984.64 | X8: =jan_26!L8 -> 19611.21
